Workbook

Sheet storico
A1: world cup | B1: ='1994'!K3 -> global penalty score | C1: ='1994'!K4 -> UEFA (Europe) penalty score | D1: ='1994'!K5 -> CONMEBOL (S. America) penalty score | E1: ='1994'!K6 -> CONCACAF (N. America) penalty score | F1: ='1994'!K7 -> CAF (Africa) penalty score | G1: ='1994'!K8 -> AFC (Asia) penalty score
A2: 1994 | B2: ='1994'!L3 -> 32.628977 | C2: ='1994'!L4 -> 18.070929 | D2: ='1994'!L5 -> 26.572114 | E2: ='1994'!L6 -> 35.401543 | F2: ='1994'!L7 -> 36.541089 | G2: ='1994'!L8 -> 65.485251
A3: 1998 | B3: ='1998'!L3 -> 42.212853 | C3: ='1998'!L4 -> 45.814247 | D3: ='1998'!L5 -> 31.699832 | E3: ='1998'!L6 -> 41.721942 | F3: ='1998'!L7 -> 69.72769 | G3: ='1998'!L8 -> 54.989856
A4: 2002 | B4: ='2002'!L3 -> 40.613611 | C4: ='2002'!L4 -> 40.820052 | D4: ='2002'!L5 -> 32.984942 | E4: ='2002'!L6 -> 38.527066 | F4: ='2002'!L7 -> 59.191837 | G4: ='2002'!L8 -> 67.570086
A5: 2006 | B5: ='2006'!L3 -> 38.281785 | C5: ='2006'!L4 -> 28.908858 | D5: ='2006'!L5 -> 32.609271 | E5: ='2006'!L6 -> 32.357509 | F5: ='2006'!L7 -> 75.040834 | G5: ='2006'!L8 -> 55.894292
A6: 2010 | B6: ='2010'!L3 -> 38.006083 | C6: ='2010'!L4 -> 17.751388 | D6: ='2010'!L5 -> 20.406373 | E6: ='2010'!L6 -> 36.874005 | F6: ='2010'!L7 -> 37.875785 | G6: ='2010'!L8 -> 56.70333
A7: 2014 | B7: ='2014'!L3 -> 31.389442 | C7: ='2014'!L4 -> 1.9230769 | D7: ='2014'!L5 -> 2.432971 | E7: ='2014'!L6 -> 13.996369 | F7: ='2014'!L7 -> 36.364798 | G7: ='2014'!L8 -> 65.16604
A8: 2018 | B8: ='2018'!L3 -> 36.271668 | C8: ='2018'!L4 -> 19.904244 | D8: ='2018'!L5 -> 6.6666667 | E8: ='2018'!L6 -> 42.604249 | F8: ='2018'!L7 -> 55.913302 | G8: ='2018'!L8 -> 81.302504
A9: 2022 | B9: ='2022'!L3 -> 35.261065 | C9: ='2022'!L4 -> 14.820119 | D9: ='2022'!L5 -> 19.898662 | E9: ='2022'!L6 -> 32.982297 | F9: ='2022'!L7 -> 47.1513 | G9: ='2022'!L8 -> 47.7802
A10: 2026 | B10: ='2026'!L3 -> 33.659678 | C10: ='2026'!L4 -> 13.184387 | D10: ='2026'!L5 -> 10.19066 | E10: ='2026'!L6 -> 11.607143 | F10: ='2026'!L7 -> 36.22409 | G10: ='2026'!L8 -> 33.621793

Sheet 1994
A1: # | B1: nation | C1: confederation | D1: points | E1: World Cup | F1: non qualify penalty | G1: qualifying penalty | I1: Qualified 24
A2: 1 | B2: Germany | C2: UEFA | D2: 60 | E2: =IF(COUNTIF($I$2:$I$25,B2)>0,1,0) -> 1 | F2: =IF(E2=1,"",1/A2) | G2: 0 | I2: United States
A3: 2 | B3: Netherlands | C3: UEFA | D3: 59 | E3: =IF(COUNTIF($I$2:$I$25,B3)>0,1,0) -> 1 | F3: =IF(E3=1,"",1/A3) | G3: =IF(E3=1,SUM(F2:$F$3),"") -> 0 | I3: Germany | K3: global penalty score | L3: =SUM(F:F)*(COUNTA(I:I)-1) -> 32.628977
A4: 3 | B4: Brazil | C4: CONMEBOL | D4: 59 | E4: =IF(COUNTIF($I$2:$I$25,B4)>0,1,0) -> 1 | F4: =IF(E4=1,"",1/A4) | G4: =IF(E4=1,SUM(F3:$F$3),"") -> 0 | I4: Mexico | K4: UEFA (Europe) penalty score | L4: =SUMIF(C:C,"UEFA",G:G)/COUNTIFS(C:C,"UEFA",E:E,1)*100 -> 18.070929
A5: 4 | B5: Italy | C5: UEFA | D5: 57 | E5: =IF(COUNTIF($I$2:$I$25,B5)>0,1,0) -> 1 | F5: =IF(E5=1,"",1/A5) | G5: =IF(E5=1,SUM(F$3:$F4),"") -> 0 | I5: Greece | K5: CONMEBOL (S. America) penalty score | L5: =SUMIF(C:C,"CONMEBOL",G:G)/COUNTIFS(C:C,"CONMEBOL",E:E,1)*100 -> 26.572114
A6: 5 | B6: Spain | C6: UEFA | D6: 56 | E6: =IF(COUNTIF($I$2:$I$25,B6)>0,1,0) -> 1 | F6: =IF(E6=1,"",1/A6) | G6: =IF(E6=1,SUM(F$3:$F5),"") -> 0 | I6: Russia | K6: CONCACAF (N. America) penalty score | L6: =SUMIF(C:C,"CONCACAF",G:G)/COUNTIFS(C:C,"CONCACAF",E:E,1)*100 -> 35.401543
A7: 6 | B7: Norway | C7: UEFA | D7: 56 | E7: =IF(COUNTIF($I$2:$I$25,B7)>0,1,0) -> 1 | F7: =IF(E7=1,"",1/A7) | G7: =IF(E7=1,SUM(F$3:$F6),"") -> 0 | I7: Colombia | K7: CAF (Africa) penalty score | L7: =SUMIF(C:C,"CAF",G:G)/COUNTIFS(C:C,"CAF",E:E,1)*100 -> 36.541089
A8: 7 | B8: Romania | C8: UEFA | D8: 55 | E8: =IF(COUNTIF($I$2:$I$25,B8)>0,1,0) -> 1 | F8: =IF(E8=1,"",1/A8) | G8: =IF(E8=1,SUM(F$3:$F7),"") -> 0 | I8: Bolivia | K8: AFC (Asia) penalty score | L8: =SUMIF(C:C,"AFC",G:G)/COUNTIFS(C:C,"AFC",E:E,1)*100 -> 65.485251
A9: 8 | B9: Argentina | C9: CONMEBOL | D9: 55 | E9: =IF(COUNTIF($I$2:$I$25,B9)>0,1,0) -> 1 | F9: =IF(E9=1,"",1/A9) | G9: =IF(E9=1,SUM(F$3:$F8),"") -> 0 | I9: Brazil
A10: 9 | B10: Denmark | C10: UEFA | D10: 55 | E10: =IF(COUNTIF($I$2:$I$25,B10)>0,1,0) -> 0 | F10: =IF(E10=1,"",1/A10) -> 0.11111111 | G10: =IF(E10=1,SUM(F$3:$F9),"") | I10: Nigeria
A11: 10 | B11: Sweden | C11: UEFA | D11: 55 | E11: =IF(COUNTIF($I$2:$I$25,B11)>0,1,0) -> 1 | F11: =IF(E11=1,"",1/A11) | G11: =IF(E11=1,SUM(F$3:$F10),"") -> 0.11111111 | I11: Cameroon
A12: 11 | B12: Nigeria | C12: CAF | D12: 54 | E12: =IF(COUNTIF($I$2:$I$25,B12)>0,1,0) -> 1 | F12: =IF(E12=1,"",1/A12) | G12: =IF(E12=1,SUM(F$3:$F11),"") -> 0.11111111 | I12: Morocco
A13: 12 | B13: Switzerland | C13: UEFA | D13: 54 | E13: =IF(COUNTIF($I$2:$I$25,B13)>0,1,0) -> 1 | F13: =IF(E13=1,"",1/A13) | G13: =IF(E13=1,SUM(F$3:$F12),"") -> 0.11111111 | I13: Norway
A14: 13 | B14: France | C14: UEFA | D14: 53 | E14: =IF(COUNTIF($I$2:$I$25,B14)>0,1,0) -> 0 | F14: =IF(E14=1,"",1/A14) -> 0.076923077 | G14: =IF(E14=1,SUM(F$3:$F13),"") | I14: South Korea
A15: 14 | B15: Republic of Ireland | C15: UEFA | D15: 53 | E15: =IF(COUNTIF($I$2:$I$25,B15)>0,1,0) -> 1 | F15: =IF(E15=1,"",1/A15) | G15: =IF(E15=1,SUM(F$3:$F14),"") -> 0.18803419 | I15: Saudi Arabia
A16: 15 | B16: England | C16: UEFA | D16: 52 | E16: =IF(COUNTIF($I$2:$I$25,B16)>0,1,0) -> 0 | F16: =IF(E16=1,"",1/A16) -> 0.066666667 | G16: =IF(E16=1,SUM(F$3:$F15),"") | I16: Sweden
A17: 16 | B17: Mexico | C17: CONCACAF | D17: 51 | E17: =IF(COUNTIF($I$2:$I$25,B17)>0,1,0) -> 1 | F17: =IF(E17=1,"",1/A17) | G17: =IF(E17=1,SUM(F$3:$F16),"") -> 0.25470085 | I17: Belgium
A18: 17 | B18: Colombia | C18: CONMEBOL | D18: 51 | E18: =IF(COUNTIF($I$2:$I$25,B18)>0,1,0) -> 1 | F18: =IF(E18=1,"",1/A18) | G18: =IF(E18=1,SUM(F$3:$F17),"") -> 0.25470085 | I18: Bulgaria
A19: 18 | B19: Uruguay | C19: CONMEBOL | D19: 50 | E19: =IF(COUNTIF($I$2:$I$25,B19)>0,1,0) -> 0 | F19: =IF(E19=1,"",1/A19) -> 0.055555556 | G19: =IF(E19=1,SUM(F$3:$F18),"") | I19: Italy
A20: 19 | B20: Russia | C20: UEFA | D20: 50 | E20: =IF(COUNTIF($I$2:$I$25,B20)>0,1,0) -> 1 | F20: =IF(E20=1,"",1/A20) | G20: =IF(E20=1,SUM(F$3:$F19),"") -> 0.31025641 | I20: Netherlands
... A25: 24 | B25: Cameroon | C25: CAF | D25: 46 | E25: =IF(COUNTIF($I$2:$I$25,B25)>0,1,0) -> 1 | F25: =IF(E25=1,"",1/A25) | G25: =IF(E25=1,SUM(F$3:$F24),"") -> 0.45333 | I25: Argentina
A26: 25 | B26: Egypt | C26: CAF | D26: 45 | E26: =IF(COUNTIF($I$2:$I$25,B26)>0,1,0) -> 0 | F26: =IF(E26=1,"",1/A26) -> 0.04 | G26: =IF(E26=1,SUM(F$3:$F25),"")
A27: 26 | B27: Ghana | C27: CAF | D27: 44 | E27: =IF(COUNTIF($I$2:$I$25,B27)>0,1,0) -> 0 | F27: =IF(E27=1,"",1/A27) -> 0.038461538 | G27: =IF(E27=1,SUM(F$3:$F26),"")
A28: 27 | B28: Belgium | C28: UEFA | D28: 44 | E28: =IF(COUNTIF($I$2:$I$25,B28)>0,1,0) -> 1 | F28: =IF(E28=1,"",1/A28) | G28: =IF(E28=1,SUM(F$3:$F27),"") -> 0.53179154
A29: 28 | B29: Morocco | C29: CAF | D29: 44 | E29: =IF(COUNTIF($I$2:$I$25,B29)>0,1,0) -> 1 | F29: =IF(E29=1,"",1/A29) | G29: =IF(E29=1,SUM(F$3:$F28),"") -> 0.53179154
A30: 29 | B30: Bulgaria | C30: UEFA | D30: 44 | E30: =IF(COUNTIF($I$2:$I$25,B30)>0,1,0) -> 1 | F30: =IF(E30=1,"",1/A30) | G30: =IF(E30=1,SUM(F$3:$F29),"") -> 0.53179154
A31: 30 | B31: Tunisia | C31: CAF | D31: 42 | E31: =IF(COUNTIF($I$2:$I$25,B31)>0,1,0) -> 0 | F31: =IF(E31=1,"",1/A31) -> 0.033333333 | G31: =IF(E31=1,SUM(F$3:$F30),"")
A32: 31 | B32: Greece | C32: UEFA | D32: 41 | E32: =IF(COUNTIF($I$2:$I$25,B32)>0,1,0) -> 1 | F32: =IF(E32=1,"",1/A32) | G32: =IF(E32=1,SUM(F$3:$F31),"") -> 0.56512488
A33: 32 | B33: Poland | C33: UEFA | D33: 41 | E33: =IF(COUNTIF($I$2:$I$25,B33)>0,1,0) -> 0 | F33: =IF(E33=1,"",1/A33) -> 0.03125 | G33: =IF(E33=1,SUM(F$3:$F32),"")
A34: 33 | B34: Scotland | C34: UEFA | D34: 40 | E34: =IF(COUNTIF($I$2:$I$25,B34)>0,1,0) -> 0 | F34: =IF(E34=1,"",1/A34) -> 0.03030303 | G34: =IF(E34=1,SUM(F$3:$F33),"")
A35: 34 | B35: Saudi Arabia | C35: AFC | D35: 40 | E35: =IF(COUNTIF($I$2:$I$25,B35)>0,1,0) -> 1 | F35: =IF(E35=1,"",1/A35) | G35: =IF(E35=1,SUM(F$3:$F34),"") -> 0.62667791
A36: 35 | B36: Wales | C36: UEFA | D36: 39 | E36: =IF(COUNTIF($I$2:$I$25,B36)>0,1,0) -> 0 | F36: =IF(E36=1,"",1/A36) -> 0.028571429 | G36: =IF(E36=1,SUM(F$3:$F35),"")
A37: 36 | B37: Austria | C37: UEFA | D37: 38 | E37: =IF(COUNTIF($I$2:$I$25,B37)>0,1,0) -> 0 | F37: =IF(E37=1,"",1/A37) -> 0.027777778 | G37: =IF(E37=1,SUM(F$3:$F36),"")
... A76: 75 | B76: Thailand | C76: AFC | D76: 22 | E76: =IF(COUNTIF($I$2:$I$25,B76)>0,1,0) -> 0 | F76: =IF(E76=1,"",1/A76) -> 0.013333333 | G76: =IF(E76=1,SUM(F$3:$F75),"")

Sheet 1998
A1: # | B1: Nation | C1: Confederation | D1: Points | E1: World Cup | F1: Penalty | G1: qualifying penalty | I1: Qualified
A2: 1 | B2: Brazil | C2: CONMEBOL | D2: 72 | E2: =IF(COUNTIF($I$2:$I$33,B2)>0,1,0) -> 1 | F2: =IF(E2=1,"",1/A2) | G2: 0 | I2: France
A3: 2 | B3: Germany | C3: UEFA | D3: 65 | E3: =IF(COUNTIF($I$2:$I$33,B3)>0,1,0) -> 1 | F3: =IF(E3=1,"",1/A3) | G3: =IF(E3=1,SUM(F2:$F$3),"") -> 0 | I3: Brazil | K3: global penalty score | L3: =SUM(F:F)*(COUNTA(I:I)-1) -> 42.212853
A4: 3 | B4: Czech Republic | C4: UEFA | D4: 65 | E4: =IF(COUNTIF($I$2:$I$33,B4)>0,1,0) -> 0 | F4: =IF(E4=1,"",1/A4) -> 0.33333333 | G4: =IF(E4=1,SUM(F3:$F$3),"") | I4: Nigeria | K4: UEFA (Europe) penalty score | L4: =SUMIF(C:C,"UEFA",G:G)/COUNTIFS(C:C,"UEFA",E:E,1)*100 -> 45.814247
A5: 4 | B5: Mexico | C5: CONCACAF | D5: 61 | E5: =IF(COUNTIF($I$2:$I$33,B5)>0,1,0) -> 1 | F5: =IF(E5=1,"",1/A5) | G5: =IF(E5=1,SUM(F$3:$F4),"") -> 0.33333333 | I5: Tunisia | K5: CONMEBOL (S. America) penalty score | L5: =SUMIF(C:C,"CONMEBOL",G:G)/COUNTIFS(C:C,"CONMEBOL",E:E,1)*100 -> 31.699832
A6: 5 | B6: England | C6: UEFA | D6: 60 | E6: =IF(COUNTIF($I$2:$I$33,B6)>0,1,0) -> 1 | F6: =IF(E6=1,"",1/A6) | G6: =IF(E6=1,SUM(F$3:$F5),"") -> 0.33333333 | I6: Morocco | K6: CONCACAF (N. America) penalty score | L6: =SUMIF(C:C,"CONCACAF",G:G)/COUNTIFS(C:C,"CONCACAF",E:E,1)*100 -> 41.721942
A7: 6 | B7: Argentina | C7: CONMEBOL | D7: 60 | E7: =IF(COUNTIF($I$2:$I$33,B7)>0,1,0) -> 1 | F7: =IF(E7=1,"",1/A7) | G7: =IF(E7=1,SUM(F$3:$F6),"") -> 0.33333333 | I7: South Africa | K7: CAF (Africa) penalty score | L7: =SUMIF(C:C,"CAF",G:G)/COUNTIFS(C:C,"CAF",E:E,1)*100 -> 69.72769
A8: 7 | B8: Norway | C8: UEFA | D8: 60 | E8: =IF(COUNTIF($I$2:$I$33,B8)>0,1,0) -> 1 | F8: =IF(E8=1,"",1/A8) | G8: =IF(E8=1,SUM(F$3:$F7),"") -> 0.33333333 | I8: Cameroon | K8: AFC (Asia) penalty score | L8: =SUMIF(C:C,"AFC",G:G)/COUNTIFS(C:C,"AFC",E:E,1)*100 -> 54.989856
A9: 8 | B9: Chile | C9: CONMEBOL | D9: 59 | E9: =IF(COUNTIF($I$2:$I$33,B9)>0,1,0) -> 1 | F9: =IF(E9=1,"",1/A9) | G9: =IF(E9=1,SUM(F$3:$F8),"") -> 0.33333333 | I9: Romania
A10: 9 | B10: Colombia | C10: CONMEBOL | D10: 58 | E10: =IF(COUNTIF($I$2:$I$33,B10)>0,1,0) -> 1 | F10: =IF(E10=1,"",1/A10) | G10: =IF(E10=1,SUM(F$3:$F9),"") -> 0.33333333 | I10: Norway
A11: 10 | B11: United States | C11: CONCACAF | D11: 58 | E11: =IF(COUNTIF($I$2:$I$33,B11)>0,1,0) -> 1 | F11: =IF(E11=1,"",1/A11) | G11: =IF(E11=1,SUM(F$3:$F10),"") -> 0.33333333 | I11: Bulgaria
A12: 11 | B12: Japan | C12: AFC | D12: 58 | E12: =IF(COUNTIF($I$2:$I$33,B12)>0,1,0) -> 1 | F12: =IF(E12=1,"",1/A12) | G12: =IF(E12=1,SUM(F$3:$F11),"") -> 0.33333333 | I12: Argentina
A13: 12 | B13: Morocco | C13: CAF | D13: 57 | E13: =IF(COUNTIF($I$2:$I$33,B13)>0,1,0) -> 1 | F13: =IF(E13=1,"",1/A13) | G13: =IF(E13=1,SUM(F$3:$F12),"") -> 0.33333333 | I13: Colombia
A14: 13 | B14: Italy | C14: UEFA | D14: 57 | E14: =IF(COUNTIF($I$2:$I$33,B14)>0,1,0) -> 1 | F14: =IF(E14=1,"",1/A14) | G14: =IF(E14=1,SUM(F$3:$F13),"") -> 0.33333333 | I14: Paraguay
A15: 14 | B15: Spain | C15: UEFA | D15: 56 | E15: =IF(COUNTIF($I$2:$I$33,B15)>0,1,0) -> 1 | F15: =IF(E15=1,"",1/A15) | G15: =IF(E15=1,SUM(F$3:$F14),"") -> 0.33333333 | I15: Denmark
A16: 15 | B16: Russia | C16: UEFA | D16: 56 | E16: =IF(COUNTIF($I$2:$I$33,B16)>0,1,0) -> 0 | F16: =IF(E16=1,"",1/A16) -> 0.066666667 | G16: =IF(E16=1,SUM(F$3:$F15),"") | I16: England
A17: 16 | B17: Egypt | C17: CAF | D17: 56 | E17: =IF(COUNTIF($I$2:$I$33,B17)>0,1,0) -> 0 | F17: =IF(E17=1,"",1/A17) -> 0.0625 | G17: =IF(E17=1,SUM(F$3:$F16),"") | I17: Austria
A18: 17 | B18: France | C18: UEFA | D18: 56 | E18: =IF(COUNTIF($I$2:$I$33,B18)>0,1,0) -> 1 | F18: =IF(E18=1,"",1/A18) | G18: =IF(E18=1,SUM(F$3:$F17),"") -> 0.4625 | I18: Spain
A19: 18 | B19: Croatia | C19: UEFA | D19: 56 | E19: =IF(COUNTIF($I$2:$I$33,B19)>0,1,0) -> 1 | F19: =IF(E19=1,"",1/A19) | G19: =IF(E19=1,SUM(F$3:$F18),"") -> 0.4625 | I19: Netherlands
A20: 19 | B20: South Korea | C20: AFC | D20: 55 | E20: =IF(COUNTIF($I$2:$I$33,B20)>0,1,0) -> 1 | F20: =IF(E20=1,"",1/A20) | G20: =IF(E20=1,SUM(F$3:$F19),"") -> 0.4625 | I20: Germany
... A33: 32 | B33: Bolivia | C33: CONMEBOL | D33: 51 | E33: =IF(COUNTIF($I$2:$I$33,B33)>0,1,0) -> 0 | F33: =IF(E33=1,"",1/A33) -> 0.03125 | G33: =IF(E33=1,SUM(F$3:$F32),"") | I33: Iran
A34: 33 | B34: Saudi Arabia | C34: AFC | D34: 51 | E34: =IF(COUNTIF($I$2:$I$33,B34)>0,1,0) -> 1 | F34: =IF(E34=1,"",1/A34) | G34: =IF(E34=1,SUM(F$3:$F33),"") -> 0.64849965
A35: 34 | B35: Bulgaria | C35: UEFA | D35: 50 | E35: =IF(COUNTIF($I$2:$I$33,B35)>0,1,0) -> 1 | F35: =IF(E35=1,"",1/A35) | G35: =IF(E35=1,SUM(F$3:$F34),"") -> 0.64849965
A36: 35 | B36: Belgium | C36: UEFA | D36: 50 | E36: =IF(COUNTIF($I$2:$I$33,B36)>0,1,0) -> 1 | F36: =IF(E36=1,"",1/A36) | G36: =IF(E36=1,SUM(F$3:$F35),"") -> 0.64849965
A37: 36 | B37: Peru | C37: CONMEBOL | D37: 50 | E37: =IF(COUNTIF($I$2:$I$33,B37)>0,1,0) -> 0 | F37: =IF(E37=1,"",1/A37) -> 0.027777778 | G37: =IF(E37=1,SUM(F$3:$F36),"")
A38: 37 | B38: Uruguay | C38: CONMEBOL | D38: 50 | E38: =IF(COUNTIF($I$2:$I$33,B38)>0,1,0) -> 0 | F38: =IF(E38=1,"",1/A38) -> 0.027027027 | G38: =IF(E38=1,SUM(F$3:$F37),"")
A39: 38 | B39: Portugal | C39: UEFA | D39: 49 | E39: =IF(COUNTIF($I$2:$I$33,B39)>0,1,0) -> 0 | F39: =IF(E39=1,"",1/A39) -> 0.026315789 | G39: =IF(E39=1,SUM(F$3:$F38),"")
A40: 39 | B40: Slovakia | C40: UEFA | D40: 49 | E40: =IF(COUNTIF($I$2:$I$33,B40)>0,1,0) -> 0 | F40: =IF(E40=1,"",1/A40) -> 0.025641026 | G40: =IF(E40=1,SUM(F$3:$F39),"")
A41: 40 | B41: Scotland | C41: UEFA | D41: 48 | E41: =IF(COUNTIF($I$2:$I$33,B41)>0,1,0) -> 1 | F41: =IF(E41=1,"",1/A41) | G41: =IF(E41=1,SUM(F$3:$F40),"") -> 0.75526127
A42: 41 | B42: Iran | C42: AFC | D42: 48 | E42: =IF(COUNTIF($I$2:$I$33,B42)>0,1,0) -> 1 | F42: =IF(E42=1,"",1/A42) | G42: =IF(E42=1,SUM(F$3:$F41),"") -> 0.75526127
A43: 42 | B43: Kuwait | C43: AFC | D43: 47 | E43: =IF(COUNTIF($I$2:$I$33,B43)>0,1,0) -> 0 | F43: =IF(E43=1,"",1/A43) -> 0.023809524 | G43: =IF(E43=1,SUM(F$3:$F42),"")
A44: 43 | B44: Ivory Coast | C44: CAF | D44: 47 | E44: =IF(COUNTIF($I$2:$I$33,B44)>0,1,0) -> 0 | F44: =IF(E44=1,"",1/A44) -> 0.023255814 | G44: =IF(E44=1,SUM(F$3:$F43),"")
A45: 44 | B45: Lithuania | C45: UEFA | D45: 47 | E45: =IF(COUNTIF($I$2:$I$33,B45)>0,1,0) -> 0 | F45: =IF(E45=1,"",1/A45) -> 0.022727273 | G45: =IF(E45=1,SUM(F$3:$F44),"")
... A76: 75 | B76: Namibia | C76: CAF | D76: 37 | E76: =IF(COUNTIF($I$2:$I$33,B76)>0,1,0) -> 0 | F76: =IF(E76=1,"",1/A76) -> 0.013333333 | G76: =IF(E76=1,SUM(F$3:$F75),"")

Sheet 2002
A1: # | B1: Nation | C1: Confederation | D1: Points | E1: World Cup | F1: Penalty | G1: qualifying penalty | I1: Qualified
A2: 1 | B2: France | C2: UEFA | D2: 802 | E2: =IF(COUNTIF($I$2:$I$33,B2)>0,1,0) -> 1 | F2: =IF(E2=1,"",1/A2) | G2: 0 | I2: Japan
A3: 2 | B3: Brazil | C3: CONMEBOL | D3: 784 | E3: =IF(COUNTIF($I$2:$I$33,B3)>0,1,0) -> 1 | F3: =IF(E3=1,"",1/A3) | G3: =IF(E3=1,SUM(F2:$F$3),"") -> 0 | I3: South Korea | K3: global penalty score | L3: =SUM(F:F)*(COUNTA(I:I)-1) -> 40.613611
A4: 3 | B4: Argentina | C4: CONMEBOL | D4: 784 | E4: =IF(COUNTIF($I$2:$I$33,B4)>0,1,0) -> 1 | F4: =IF(E4=1,"",1/A4) | G4: =IF(E4=1,SUM(F3:$F$3),"") -> 0 | I4: France | K4: UEFA (Europe) penalty score | L4: =SUMIF(C:C,"UEFA",G:G)/COUNTIFS(C:C,"UEFA",E:E,1)*100 -> 40.820052
A5: 4 | B5: Colombia | C5: CONMEBOL | D5: 728 | E5: =IF(COUNTIF($I$2:$I$33,B5)>0,1,0) -> 0 | F5: =IF(E5=1,"",1/A5) -> 0.25 | G5: =IF(E5=1,SUM(F$3:$F4),"") | I5: Cameroon | K5: CONMEBOL (S. America) penalty score | L5: =SUMIF(C:C,"CONMEBOL",G:G)/COUNTIFS(C:C,"CONMEBOL",E:E,1)*100 -> 32.984942
A6: 5 | B6: Portugal | C6: UEFA | D6: 726 | E6: =IF(COUNTIF($I$2:$I$33,B6)>0,1,0) -> 1 | F6: =IF(E6=1,"",1/A6) | G6: =IF(E6=1,SUM(F$3:$F5),"") -> 0.25 | I6: South Africa | K6: CONCACAF (N. America) penalty score | L6: =SUMIF(C:C,"CONCACAF",G:G)/COUNTIFS(C:C,"CONCACAF",E:E,1)*100 -> 38.527066
A7: 6 | B7: Italy | C7: UEFA | D7: 717 | E7: =IF(COUNTIF($I$2:$I$33,B7)>0,1,0) -> 1 | F7: =IF(E7=1,"",1/A7) | G7: =IF(E7=1,SUM(F$3:$F6),"") -> 0.25 | I7: Tunisia | K7: CAF (Africa) penalty score | L7: =SUMIF(C:C,"CAF",G:G)/COUNTIFS(C:C,"CAF",E:E,1)*100 -> 59.191837
A8: 7 | B8: Mexico | C8: CONCACAF | D8: 716 | E8: =IF(COUNTIF($I$2:$I$33,B8)>0,1,0) -> 1 | F8: =IF(E8=1,"",1/A8) | G8: =IF(E8=1,SUM(F$3:$F7),"") -> 0.25 | I8: Senegal | K8: AFC (Asia) penalty score | L8: =SUMIF(C:C,"AFC",G:G)/COUNTIFS(C:C,"AFC",E:E,1)*100 -> 67.570086
A9: 8 | B9: Spain | C9: UEFA | D9: 713 | E9: =IF(COUNTIF($I$2:$I$33,B9)>0,1,0) -> 1 | F9: =IF(E9=1,"",1/A9) | G9: =IF(E9=1,SUM(F$3:$F8),"") -> 0.25 | I9: Nigeria
A10: 9 | B10: Netherlands | C10: UEFA | D10: 703 | E10: =IF(COUNTIF($I$2:$I$33,B10)>0,1,0) -> 0 | F10: =IF(E10=1,"",1/A10) -> 0.11111111 | G10: =IF(E10=1,SUM(F$3:$F9),"") | I10: Argentina
A11: 10 | B11: Germany | C11: UEFA | D11: 695 | E11: =IF(COUNTIF($I$2:$I$33,B11)>0,1,0) -> 1 | F11: =IF(E11=1,"",1/A11) | G11: =IF(E11=1,SUM(F$3:$F10),"") -> 0.36111111 | I11: Poland
A12: 11 | B12: England | C12: UEFA | D12: 694 | E12: =IF(COUNTIF($I$2:$I$33,B12)>0,1,0) -> 1 | F12: =IF(E12=1,"",1/A12) | G12: =IF(E12=1,SUM(F$3:$F11),"") -> 0.36111111 | I12: Sweden
A13: 12 | B13: United States | C13: CONCACAF | D13: 690 | E13: =IF(COUNTIF($I$2:$I$33,B13)>0,1,0) -> 1 | F13: =IF(E13=1,"",1/A13) | G13: =IF(E13=1,SUM(F$3:$F12),"") -> 0.36111111 | I13: Spain
A14: 13 | B14: Romania | C14: UEFA | D14: 675 | E14: =IF(COUNTIF($I$2:$I$33,B14)>0,1,0) -> 0 | F14: =IF(E14=1,"",1/A14) -> 0.076923077 | G14: =IF(E14=1,SUM(F$3:$F13),"") | I14: Costa Rica
A15: 14 | B15: Republic of Ireland | C15: UEFA | D15: 674 | E15: =IF(COUNTIF($I$2:$I$33,B15)>0,1,0) -> 1 | F15: =IF(E15=1,"",1/A15) | G15: =IF(E15=1,SUM(F$3:$F14),"") -> 0.43803419 | I15: Russia
A16: 15 | B16: Czech Republic | C16: UEFA | D16: 674 | E16: =IF(COUNTIF($I$2:$I$33,B16)>0,1,0) -> 0 | F16: =IF(E16=1,"",1/A16) -> 0.066666667 | G16: =IF(E16=1,SUM(F$3:$F15),"") | I16: Portugal
A17: 16 | B17: Cameroon | C17: CAF | D17: 672 | E17: =IF(COUNTIF($I$2:$I$33,B17)>0,1,0) -> 1 | F17: =IF(E17=1,"",1/A17) | G17: =IF(E17=1,SUM(F$3:$F16),"") -> 0.50470085 | I17: Denmark
A18: 17 | B18: Paraguay | C18: CONMEBOL | D18: 671 | E18: =IF(COUNTIF($I$2:$I$33,B18)>0,1,0) -> 1 | F18: =IF(E18=1,"",1/A18) | G18: =IF(E18=1,SUM(F$3:$F17),"") -> 0.50470085 | I18: Croatia
A19: 18 | B19: Sweden | C19: UEFA | D19: 665 | E19: =IF(COUNTIF($I$2:$I$33,B19)>0,1,0) -> 1 | F19: =IF(E19=1,"",1/A19) | G19: =IF(E19=1,SUM(F$3:$F18),"") -> 0.50470085 | I19: Italy
A20: 19 | B20: Denmark | C20: UEFA | D20: 657 | E20: =IF(COUNTIF($I$2:$I$33,B20)>0,1,0) -> 1 | F20: =IF(E20=1,"",1/A20) | G20: =IF(E20=1,SUM(F$3:$F19),"") -> 0.50470085 | I20: England
... A33: 32 | B33: Norway | C33: UEFA | D33: 631 | E33: =IF(COUNTIF($I$2:$I$33,B33)>0,1,0) -> 0 | F33: =IF(E33=1,"",1/A33) -> 0.03125 | G33: =IF(E33=1,SUM(F$3:$F32),"") | I33: Uruguay
A34: 33 | B34: Saudi Arabia | C34: AFC | D34: 627 | E34: =IF(COUNTIF($I$2:$I$33,B34)>0,1,0) -> 1 | F34: =IF(E34=1,"",1/A34) | G34: =IF(E34=1,SUM(F$3:$F33),"") -> 0.61043361
A35: 34 | B35: Trinidad and | C35: CONCACAF | D35: 624 | E35: =IF(COUNTIF($I$2:$I$33,B35)>0,1,0) -> 0 | F35: =IF(E35=1,"",1/A35) -> 0.029411765 | G35: =IF(E35=1,SUM(F$3:$F34),"")
A36: 35 | B36: Ecuador | C36: CONMEBOL | D36: 624 | E36: =IF(COUNTIF($I$2:$I$33,B36)>0,1,0) -> 1 | F36: =IF(E36=1,"",1/A36) | G36: =IF(E36=1,SUM(F$3:$F35),"") -> 0.63984538
A37: 36 | B37: South Africa | C37: CAF | D37: 623 | E37: =IF(COUNTIF($I$2:$I$33,B37)>0,1,0) -> 1 | F37: =IF(E37=1,"",1/A37) | G37: =IF(E37=1,SUM(F$3:$F36),"") -> 0.63984538
A38: 37 | B38: Poland | C38: UEFA | D38: 615 | E38: =IF(COUNTIF($I$2:$I$33,B38)>0,1,0) -> 1 | F38: =IF(E38=1,"",1/A38) | G38: =IF(E38=1,SUM(F$3:$F37),"") -> 0.63984538
A39: 38 | B39: Morocco | C39: CAF | D39: 612 | E39: =IF(COUNTIF($I$2:$I$33,B39)>0,1,0) -> 0 | F39: =IF(E39=1,"",1/A39) -> 0.026315789 | G39: =IF(E39=1,SUM(F$3:$F38),"")
A40: 39 | B40: South Korea | C40: AFC | D40: 603 | E40: =IF(COUNTIF($I$2:$I$33,B40)>0,1,0) -> 1 | F40: =IF(E40=1,"",1/A40) | G40: =IF(E40=1,SUM(F$3:$F39),"") -> 0.66616117
A41: 40 | B41: Finland | C41: UEFA | D41: 600 | E41: =IF(COUNTIF($I$2:$I$33,B41)>0,1,0) -> 0 | F41: =IF(E41=1,"",1/A41) -> 0.025 | G41: =IF(E41=1,SUM(F$3:$F40),"")
A42: 41 | B42: Senegal | C42: CAF | D42: 599 | E42: =IF(COUNTIF($I$2:$I$33,B42)>0,1,0) -> 1 | F42: =IF(E42=1,"",1/A42) | G42: =IF(E42=1,SUM(F$3:$F41),"") -> 0.69116117
A43: 42 | B43: Egypt | C43: CAF | D43: 598 | E43: =IF(COUNTIF($I$2:$I$33,B43)>0,1,0) -> 0 | F43: =IF(E43=1,"",1/A43) -> 0.023809524 | G43: =IF(E43=1,SUM(F$3:$F42),"")
A44: 43 | B44: Ukraine | C44: UEFA | D44: 593 | E44: =IF(COUNTIF($I$2:$I$33,B44)>0,1,0) -> 0 | F44: =IF(E44=1,"",1/A44) -> 0.023255814 | G44: =IF(E44=1,SUM(F$3:$F43),"")
A45: 44 | B45: Chile | C45: CONMEBOL | D45: 590 | E45: =IF(COUNTIF($I$2:$I$33,B45)>0,1,0) -> 0 | F45: =IF(E45=1,"",1/A45) -> 0.022727273 | G45: =IF(E45=1,SUM(F$3:$F44),"")
... A76: 75 | B76: Liberia | C76: CAF | D76: 500 | E76: =IF(COUNTIF($I$2:$I$33,B76)>0,1,0) -> 0 | F76: =IF(E76=1,"",1/A76) -> 0.013333333 | G76: =IF(E76=1,SUM(F$3:$F75),"")

Sheet 2006
A1: # | B1: Nation | C1: Confederation | D1: Points | E1: World Cup | F1: Penalty | G1: qualifying penalty | I1: Qualified
A2: 1 | B2: Brazil | C2: CONMEBOL | D2: 827 | E2: =IF(COUNTIF($I$2:$I$33,B2)>0,1,0) -> 1 | F2: =IF(E2=1,"",1/A2) | G2: 0 | I2: Germany
A3: 2 | B3: Czech Republic | C3: UEFA | D3: 772 | E3: =IF(COUNTIF($I$2:$I$33,B3)>0,1,0) -> 1 | F3: =IF(E3=1,"",1/A3) | G3: =IF(E3=1,SUM(F2:$F$3),"") -> 0 | I3: Japan | K3: global penalty score | L3: =SUM(F:F)*(COUNTA(I:I)-1) -> 38.281785
A4: 3 | B4: Netherlands | C4: UEFA | D4: 768 | E4: =IF(COUNTIF($I$2:$I$33,B4)>0,1,0) -> 1 | F4: =IF(E4=1,"",1/A4) | G4: =IF(E4=1,SUM(F3:$F$3),"") -> 0 | I4: Saudi Arabia | K4: UEFA (Europe) penalty score | L4: =SUMIF(C:C,"UEFA",G:G)/COUNTIFS(C:C,"UEFA",E:E,1)*100 -> 28.908858
A5: 4 | B5: Mexico | C5: CONCACAF | D5: 758 | E5: =IF(COUNTIF($I$2:$I$33,B5)>0,1,0) -> 1 | F5: =IF(E5=1,"",1/A5) | G5: =IF(E5=1,SUM(F$3:$F4),"") -> 0 | I5: South Korea | K5: CONMEBOL (S. America) penalty score | L5: =SUMIF(C:C,"CONMEBOL",G:G)/COUNTIFS(C:C,"CONMEBOL",E:E,1)*100 -> 32.609271
A6: 5 | B6: Spain | C6: UEFA | D6: 756 | E6: =IF(COUNTIF($I$2:$I$33,B6)>0,1,0) -> 1 | F6: =IF(E6=1,"",1/A6) | G6: =IF(E6=1,SUM(F$3:$F5),"") -> 0 | I6: Iran | K6: CONCACAF (N. America) penalty score | L6: =SUMIF(C:C,"CONCACAF",G:G)/COUNTIFS(C:C,"CONCACAF",E:E,1)*100 -> 32.357509
A7: 6 | B7: United States | C7: CONCACAF | D7: 756 | E7: =IF(COUNTIF($I$2:$I$33,B7)>0,1,0) -> 1 | F7: =IF(E7=1,"",1/A7) | G7: =IF(E7=1,SUM(F$3:$F6),"") -> 0 | I7: Argentina | K7: CAF (Africa) penalty score | L7: =SUMIF(C:C,"CAF",G:G)/COUNTIFS(C:C,"CAF",E:E,1)*100 -> 75.040834
A8: 7 | B8: Portugal | C8: UEFA | D8: 750 | E8: =IF(COUNTIF($I$2:$I$33,B8)>0,1,0) -> 1 | F8: =IF(E8=1,"",1/A8) | G8: =IF(E8=1,SUM(F$3:$F7),"") -> 0 | I8: Ukraine | K8: AFC (Asia) penalty score | L8: =SUMIF(C:C,"AFC",G:G)/COUNTIFS(C:C,"AFC",E:E,1)*100 -> 55.894292
A9: 8 | B9: France | C9: UEFA | D9: 749 | E9: =IF(COUNTIF($I$2:$I$33,B9)>0,1,0) -> 1 | F9: =IF(E9=1,"",1/A9) | G9: =IF(E9=1,SUM(F$3:$F8),"") -> 0 | I9: United States
A10: 9 | B10: Argentina | C10: CONMEBOL | D10: 746 | E10: =IF(COUNTIF($I$2:$I$33,B10)>0,1,0) -> 1 | F10: =IF(E10=1,"",1/A10) | G10: =IF(E10=1,SUM(F$3:$F9),"") -> 0 | I10: Brazil
A11: 10 | B11: England | C11: UEFA | D11: 741 | E11: =IF(COUNTIF($I$2:$I$33,B11)>0,1,0) -> 1 | F11: =IF(E11=1,"",1/A11) | G11: =IF(E11=1,SUM(F$3:$F10),"") -> 0 | I11: Mexico
A12: 11 | B12: Denmark | C12: UEFA | D12: 736 | E12: =IF(COUNTIF($I$2:$I$33,B12)>0,1,0) -> 0 | F12: =IF(E12=1,"",1/A12) -> 0.090909091 | G12: =IF(E12=1,SUM(F$3:$F11),"") | I12: Ghana
A13: 12 | B13: Nigeria | C13: CAF | D13: 736 | E13: =IF(COUNTIF($I$2:$I$33,B13)>0,1,0) -> 0 | F13: =IF(E13=1,"",1/A13) -> 0.083333333 | G13: =IF(E13=1,SUM(F$3:$F12),"") | I13: Togo
A14: 13 | B14: Italy | C14: UEFA | D14: 728 | E14: =IF(COUNTIF($I$2:$I$33,B14)>0,1,0) -> 1 | F14: =IF(E14=1,"",1/A14) | G14: =IF(E14=1,SUM(F$3:$F13),"") -> 0.17424242 | I14: England
A15: 14 | B15: Turkey | C15: UEFA | D15: 726 | E15: =IF(COUNTIF($I$2:$I$33,B15)>0,1,0) -> 0 | F15: =IF(E15=1,"",1/A15) -> 0.071428571 | G15: =IF(E15=1,SUM(F$3:$F14),"") | I15: Poland
A16: 15 | B16: Cameroon | C16: CAF | D16: 722 | E16: =IF(COUNTIF($I$2:$I$33,B16)>0,1,0) -> 0 | F16: =IF(E16=1,"",1/A16) -> 0.066666667 | G16: =IF(E16=1,SUM(F$3:$F15),"") | I16: Angola
A17: 16 | B17: Sweden | C17: UEFA | D17: 709 | E17: =IF(COUNTIF($I$2:$I$33,B17)>0,1,0) -> 1 | F17: =IF(E17=1,"",1/A17) | G17: =IF(E17=1,SUM(F$3:$F16),"") -> 0.31233766 | I17: Ivory Coast
A18: 17 | B18: Egypt | C18: CAF | D18: 708 | E18: =IF(COUNTIF($I$2:$I$33,B18)>0,1,0) -> 0 | F18: =IF(E18=1,"",1/A18) -> 0.058823529 | G18: =IF(E18=1,SUM(F$3:$F17),"") | I18: Tunisia
A19: 18 | B19: Japan | C19: AFC | D19: 705 | E19: =IF(COUNTIF($I$2:$I$33,B19)>0,1,0) -> 1 | F19: =IF(E19=1,"",1/A19) | G19: =IF(E19=1,SUM(F$3:$F18),"") -> 0.37116119 | I19: Croatia
A20: 19 | B20: Germany | C20: UEFA | D20: 696 | E20: =IF(COUNTIF($I$2:$I$33,B20)>0,1,0) -> 1 | F20: =IF(E20=1,"",1/A20) | G20: =IF(E20=1,SUM(F$3:$F19),"") -> 0.37116119 | I20: Netherlands
... A33: 32 | B33: Ivory Coast | C33: CAF | D33: 669 | E33: =IF(COUNTIF($I$2:$I$33,B33)>0,1,0) -> 1 | F33: =IF(E33=1,"",1/A33) | G33: =IF(E33=1,SUM(F$3:$F32),"") -> 0.61162512 | I33: Switzerland
A34: 33 | B34: Paraguay | C34: CONMEBOL | D34: 653 | E34: =IF(COUNTIF($I$2:$I$33,B34)>0,1,0) -> 1 | F34: =IF(E34=1,"",1/A34) | G34: =IF(E34=1,SUM(F$3:$F33),"") -> 0.61162512
A35: 34 | B35: Saudi Arabia | C35: AFC | D35: 651 | E35: =IF(COUNTIF($I$2:$I$33,B35)>0,1,0) -> 1 | F35: =IF(E35=1,"",1/A35) | G35: =IF(E35=1,SUM(F$3:$F34),"") -> 0.61162512
A36: 35 | B36: Switzerland | C36: UEFA | D36: 648 | E36: =IF(COUNTIF($I$2:$I$33,B36)>0,1,0) -> 1 | F36: =IF(E36=1,"",1/A36) | G36: =IF(E36=1,SUM(F$3:$F35),"") -> 0.61162512
A37: 36 | B37: Morocco | C37: CAF | D37: 646 | E37: =IF(COUNTIF($I$2:$I$33,B37)>0,1,0) -> 0 | F37: =IF(E37=1,"",1/A37) -> 0.027777778 | G37: =IF(E37=1,SUM(F$3:$F36),"")
A38: 37 | B38: Russia | C38: UEFA | D38: 645 | E38: =IF(COUNTIF($I$2:$I$33,B38)>0,1,0) -> 0 | F38: =IF(E38=1,"",1/A38) -> 0.027027027 | G38: =IF(E38=1,SUM(F$3:$F37),"")
A39: 38 | B39: Bulgaria | C39: UEFA | D39: 645 | E39: =IF(COUNTIF($I$2:$I$33,B39)>0,1,0) -> 0 | F39: =IF(E39=1,"",1/A39) -> 0.026315789 | G39: =IF(E39=1,SUM(F$3:$F38),"")
A40: 39 | B40: Ecuador | C40: CONMEBOL | D40: 631 | E40: =IF(COUNTIF($I$2:$I$33,B40)>0,1,0) -> 1 | F40: =IF(E40=1,"",1/A40) | G40: =IF(E40=1,SUM(F$3:$F39),"") -> 0.69274572
A41: 40 | B41: Norway | C41: UEFA | D41: 627 | E41: =IF(COUNTIF($I$2:$I$33,B41)>0,1,0) -> 0 | F41: =IF(E41=1,"",1/A41) -> 0.025 | G41: =IF(E41=1,SUM(F$3:$F40),"")
A42: 41 | B42: Slovakia | C42: UEFA | D42: 613 | E42: =IF(COUNTIF($I$2:$I$33,B42)>0,1,0) -> 0 | F42: =IF(E42=1,"",1/A42) -> 0.024390244 | G42: =IF(E42=1,SUM(F$3:$F41),"")
A43: 42 | B43: Honduras | C43: CONCACAF | D43: 612 | E43: =IF(COUNTIF($I$2:$I$33,B43)>0,1,0) -> 0 | F43: =IF(E43=1,"",1/A43) -> 0.023809524 | G43: =IF(E43=1,SUM(F$3:$F42),"")
A44: 43 | B44: Australia | C44: AFC | D44: 612 | E44: =IF(COUNTIF($I$2:$I$33,B44)>0,1,0) -> 1 | F44: =IF(E44=1,"",1/A44) | G44: =IF(E44=1,SUM(F$3:$F43),"") -> 0.76594549
A45: 44 | B45: Serbia and Montenegro | C45: UEFA | D45: 610 | E45: =IF(COUNTIF($I$2:$I$33,B45)>0,1,0) -> 1 | F45: =IF(E45=1,"",1/A45) | G45: =IF(E45=1,SUM(F$3:$F44),"") -> 0.76594549
... A76: 75 | B76: Kuwait | C76: AFC | D76: 538 | E76: =IF(COUNTIF($I$2:$I$33,B76)>0,1,0) -> 0 | F76: =IF(E76=1,"",1/A76) -> 0.013333333 | G76: =IF(E76=1,SUM(F$3:$F75),"")

Sheet 2010
A1: # | B1: Nation | C1: Confederation | D1: Points | E1: World Cup | F1: Penalty | G1: qualifying penalty | I1: Qualified
A2: 1 | B2: Brazil | C2: CONMEBOL | D2: 1611 | E2: =IF(COUNTIF($I$2:$I$33,B2)>0,1,0) -> 1 | F2: =IF(E2=1,"",1/A2) | G2: 0 | I2: South Africa
A3: 2 | B3: Spain | C3: UEFA | D3: 1565 | E3: =IF(COUNTIF($I$2:$I$33,B3)>0,1,0) -> 1 | F3: =IF(E3=1,"",1/A3) | G3: =IF(E3=1,SUM(F2:$F$3),"") -> 0 | I3: Japan | K3: global penalty score | L3: =SUM(F:F)*(COUNTA(I:I)-1) -> 38.006083
A4: 3 | B4: Portugal | C4: UEFA | D4: 1249 | E4: =IF(COUNTIF($I$2:$I$33,B4)>0,1,0) -> 1 | F4: =IF(E4=1,"",1/A4) | G4: =IF(E4=1,SUM(F3:$F$3),"") -> 0 | I4: Australia | K4: UEFA (Europe) penalty score | L4: =SUMIF(C:C,"UEFA",G:G)/COUNTIFS(C:C,"UEFA",E:E,1)*100 -> 17.751388
A5: 4 | B5: Netherlands | C5: UEFA | D5: 1231 | E5: =IF(COUNTIF($I$2:$I$33,B5)>0,1,0) -> 1 | F5: =IF(E5=1,"",1/A5) | G5: =IF(E5=1,SUM(F$3:$F4),"") -> 0 | I5: South Korea | K5: CONMEBOL (S. America) penalty score | L5: =SUMIF(C:C,"CONMEBOL",G:G)/COUNTIFS(C:C,"CONMEBOL",E:E,1)*100 -> 20.406373
A6: 5 | B6: Italy | C6: UEFA | D6: 1184 | E6: =IF(COUNTIF($I$2:$I$33,B6)>0,1,0) -> 1 | F6: =IF(E6=1,"",1/A6) | G6: =IF(E6=1,SUM(F$3:$F5),"") -> 0 | I6: Netherlands | K6: CONCACAF (N. America) penalty score | L6: =SUMIF(C:C,"CONCACAF",G:G)/COUNTIFS(C:C,"CONCACAF",E:E,1)*100 -> 36.874005
A7: 6 | B7: Germany | C7: UEFA | D7: 1082 | E7: =IF(COUNTIF($I$2:$I$33,B7)>0,1,0) -> 1 | F7: =IF(E7=1,"",1/A7) | G7: =IF(E7=1,SUM(F$3:$F6),"") -> 0 | I7: North Korea | K7: CAF (Africa) penalty score | L7: =SUMIF(C:C,"CAF",G:G)/COUNTIFS(C:C,"CAF",E:E,1)*100 -> 37.875785
A8: 7 | B8: Argentina | C8: CONMEBOL | D8: 1076 | E8: =IF(COUNTIF($I$2:$I$33,B8)>0,1,0) -> 1 | F8: =IF(E8=1,"",1/A8) | G8: =IF(E8=1,SUM(F$3:$F7),"") -> 0 | I8: Brazil | K8: AFC (Asia) penalty score | L8: =SUMIF(C:C,"AFC",G:G)/COUNTIFS(C:C,"AFC",E:E,1)*100 -> 56.70333
A9: 8 | B9: England | C9: UEFA | D9: 1068 | E9: =IF(COUNTIF($I$2:$I$33,B9)>0,1,0) -> 1 | F9: =IF(E9=1,"",1/A9) | G9: =IF(E9=1,SUM(F$3:$F8),"") -> 0 | I9: Ghana
A10: 9 | B10: France | C10: UEFA | D10: 1044 | E10: =IF(COUNTIF($I$2:$I$33,B10)>0,1,0) -> 1 | F10: =IF(E10=1,"",1/A10) | G10: =IF(E10=1,SUM(F$3:$F9),"") -> 0 | I10: England
A11: 10 | B11: Croatia | C11: UEFA | D11: 1041 | E11: =IF(COUNTIF($I$2:$I$33,B11)>0,1,0) -> 0 | F11: =IF(E11=1,"",1/A11) -> 0.1 | G11: =IF(E11=1,SUM(F$3:$F10),"") | I11: Spain
A12: 11 | B12: Russia | C12: UEFA | D12: 1015 | E12: =IF(COUNTIF($I$2:$I$33,B12)>0,1,0) -> 0 | F12: =IF(E12=1,"",1/A12) -> 0.090909091 | G12: =IF(E12=1,SUM(F$3:$F11),"") | I12: Paraguay
A13: 12 | B13: Egypt | C13: CAF | D13: 967 | E13: =IF(COUNTIF($I$2:$I$33,B13)>0,1,0) -> 0 | F13: =IF(E13=1,"",1/A13) -> 0.083333333 | G13: =IF(E13=1,SUM(F$3:$F12),"") | I13: Ivory Coast
A14: 13 | B14: Greece | C14: UEFA | D14: 964 | E14: =IF(COUNTIF($I$2:$I$33,B14)>0,1,0) -> 1 | F14: =IF(E14=1,"",1/A14) | G14: =IF(E14=1,SUM(F$3:$F13),"") -> 0.27424242 | I14: Germany
A15: 14 | B15: United States | C15: CONCACAF | D15: 957 | E15: =IF(COUNTIF($I$2:$I$33,B15)>0,1,0) -> 1 | F15: =IF(E15=1,"",1/A15) | G15: =IF(E15=1,SUM(F$3:$F14),"") -> 0.27424242 | I15: Denmark
A16: 15 | B16: Serbia | C16: UEFA | D16: 947 | E16: =IF(COUNTIF($I$2:$I$33,B16)>0,1,0) -> 1 | F16: =IF(E16=1,"",1/A16) | G16: =IF(E16=1,SUM(F$3:$F15),"") -> 0.27424242 | I16: Serbia
A17: 16 | B17: Uruguay | C17: CONMEBOL | D17: 899 | E17: =IF(COUNTIF($I$2:$I$33,B17)>0,1,0) -> 1 | F17: =IF(E17=1,"",1/A17) | G17: =IF(E17=1,SUM(F$3:$F16),"") -> 0.27424242 | I17: Italy
A18: 17 | B18: Mexico | C18: CONCACAF | D18: 895 | E18: =IF(COUNTIF($I$2:$I$33,B18)>0,1,0) -> 1 | F18: =IF(E18=1,"",1/A18) | G18: =IF(E18=1,SUM(F$3:$F17),"") -> 0.27424242 | I18: Chile
A19: 18 | B19: Chile | C19: CONMEBOL | D19: 888 | E19: =IF(COUNTIF($I$2:$I$33,B19)>0,1,0) -> 1 | F19: =IF(E19=1,"",1/A19) | G19: =IF(E19=1,SUM(F$3:$F18),"") -> 0.27424242 | I19: Mexico
A20: 19 | B20: Cameroon | C20: CAF | D20: 887 | E20: =IF(COUNTIF($I$2:$I$33,B20)>0,1,0) -> 1 | F20: =IF(E20=1,"",1/A20) | G20: =IF(E20=1,SUM(F$3:$F19),"") -> 0.27424242 | I20: United States
... A33: 32 | B33: Ghana | C33: CAF | D33: 800 | E33: =IF(COUNTIF($I$2:$I$33,B33)>0,1,0) -> 1 | F33: =IF(E33=1,"",1/A33) | G33: =IF(E33=1,SUM(F$3:$F32),"") -> 0.47183381 | I33: Uruguay
A34: 33 | B34: Czech Republic | C34: UEFA | D34: 793 | E34: =IF(COUNTIF($I$2:$I$33,B34)>0,1,0) -> 0 | F34: =IF(E34=1,"",1/A34) -> 0.03030303 | G34: =IF(E34=1,SUM(F$3:$F33),"")
A35: 34 | B35: Slovakia | C35: UEFA | D35: 777 | E35: =IF(COUNTIF($I$2:$I$33,B35)>0,1,0) -> 1 | F35: =IF(E35=1,"",1/A35) | G35: =IF(E35=1,SUM(F$3:$F34),"") -> 0.50213684
A36: 35 | B36: Colombia | C36: CONMEBOL | D36: 776 | E36: =IF(COUNTIF($I$2:$I$33,B36)>0,1,0) -> 0 | F36: =IF(E36=1,"",1/A36) -> 0.028571429 | G36: =IF(E36=1,SUM(F$3:$F35),"")
A37: 36 | B37: Denmark | C37: UEFA | D37: 767 | E37: =IF(COUNTIF($I$2:$I$33,B37)>0,1,0) -> 1 | F37: =IF(E37=1,"",1/A37) | G37: =IF(E37=1,SUM(F$3:$F36),"") -> 0.53070827
A38: 37 | B38: Sweden | C38: UEFA | D38: 761 | E38: =IF(COUNTIF($I$2:$I$33,B38)>0,1,0) -> 0 | F38: =IF(E38=1,"",1/A38) -> 0.027027027 | G38: =IF(E38=1,SUM(F$3:$F37),"")
A39: 38 | B39: Honduras | C39: CONCACAF | D39: 734 | E39: =IF(COUNTIF($I$2:$I$33,B39)>0,1,0) -> 1 | F39: =IF(E39=1,"",1/A39) | G39: =IF(E39=1,SUM(F$3:$F38),"") -> 0.5577353
A40: 39 | B40: Bulgaria | C40: UEFA | D40: 711 | E40: =IF(COUNTIF($I$2:$I$33,B40)>0,1,0) -> 0 | F40: =IF(E40=1,"",1/A40) -> 0.025641026 | G40: =IF(E40=1,SUM(F$3:$F39),"")
A41: 40 | B41: Costa Rica | C41: CONCACAF | D41: 710 | E41: =IF(COUNTIF($I$2:$I$33,B41)>0,1,0) -> 0 | F41: =IF(E41=1,"",1/A41) -> 0.025 | G41: =IF(E41=1,SUM(F$3:$F40),"")
A42: 41 | B42: Republic of Ireland | C42: UEFA | D42: 709 | E42: =IF(COUNTIF($I$2:$I$33,B42)>0,1,0) -> 0 | F42: =IF(E42=1,"",1/A42) -> 0.024390244 | G42: =IF(E42=1,SUM(F$3:$F41),"")
A43: 42 | B43: Gabon | C43: CAF | D43: 700 | E43: =IF(COUNTIF($I$2:$I$33,B43)>0,1,0) -> 0 | F43: =IF(E43=1,"",1/A43) -> 0.023809524 | G43: =IF(E43=1,SUM(F$3:$F42),"")
A44: 43 | B44: Scotland | C44: UEFA | D44: 699 | E44: =IF(COUNTIF($I$2:$I$33,B44)>0,1,0) -> 0 | F44: =IF(E44=1,"",1/A44) -> 0.023255814 | G44: =IF(E44=1,SUM(F$3:$F43),"")
A45: 44 | B45: Ecuador | C45: CONMEBOL | D45: 694 | E45: =IF(COUNTIF($I$2:$I$33,B45)>0,1,0) -> 0 | F45: =IF(E45=1,"",1/A45) -> 0.022727273 | G45: =IF(E45=1,SUM(F$3:$F44),"")
... A76: 75 | B76: Senegal | C76: CAF | D76: 422 | E76: =IF(COUNTIF($I$2:$I$33,B76)>0,1,0) -> 0 | F76: =IF(E76=1,"",1/A76) -> 0.013333333 | G76: =IF(E76=1,SUM(F$3:$F75),"")

Sheet 2014
A1: # | B1: Nation | C1: Confederation | D1: Points | E1: World Cup | F1: Penalty | G1: qualifying penalty | I1: Qualified
A2: 1 | B2: Spain | C2: UEFA | D2: 1485 | E2: =IF(COUNTIF($I$2:$I$33,B2)>0,1,0) -> 1 | F2: =IF(E2=1,"",1/A2) | G2: 0 | I2: Brazil
A3: 2 | B3: Germany | C3: UEFA | D3: 1300 | E3: =IF(COUNTIF($I$2:$I$33,B3)>0,1,0) -> 1 | F3: =IF(E3=1,"",1/A3) | G3: =IF(E3=1,SUM(F2:$F$3),"") -> 0 | I3: Japan | K3: global penalty score | L3: =SUM(F:F)*(COUNTA(I:I)-1) -> 31.389442
A4: 3 | B4: Brazil | C4: CONMEBOL | D4: 1242 | E4: =IF(COUNTIF($I$2:$I$33,B4)>0,1,0) -> 1 | F4: =IF(E4=1,"",1/A4) | G4: =IF(E4=1,SUM(F3:$F$3),"") -> 0 | I4: Australia | K4: UEFA (Europe) penalty score | L4: =SUMIF(C:C,"UEFA",G:G)/COUNTIFS(C:C,"UEFA",E:E,1)*100 -> 1.9230769
A5: 4 | B5: Portugal | C5: UEFA | D5: 1189 | E5: =IF(COUNTIF($I$2:$I$33,B5)>0,1,0) -> 1 | F5: =IF(E5=1,"",1/A5) | G5: =IF(E5=1,SUM(F$3:$F4),"") -> 0 | I5: Iran | K5: CONMEBOL (S. America) penalty score | L5: =SUMIF(C:C,"CONMEBOL",G:G)/COUNTIFS(C:C,"CONMEBOL",E:E,1)*100 -> 2.432971
A6: 5 | B6: Argentina | C6: CONMEBOL | D6: 1175 | E6: =IF(COUNTIF($I$2:$I$33,B6)>0,1,0) -> 1 | F6: =IF(E6=1,"",1/A6) | G6: =IF(E6=1,SUM(F$3:$F5),"") -> 0 | I6: South Korea | K6: CONCACAF (N. America) penalty score | L6: =SUMIF(C:C,"CONCACAF",G:G)/COUNTIFS(C:C,"CONCACAF",E:E,1)*100 -> 13.996369
A7: 6 | B7: Switzerland | C7: UEFA | D7: 1149 | E7: =IF(COUNTIF($I$2:$I$33,B7)>0,1,0) -> 1 | F7: =IF(E7=1,"",1/A7) | G7: =IF(E7=1,SUM(F$3:$F6),"") -> 0 | I7: Netherlands | K7: CAF (Africa) penalty score | L7: =SUMIF(C:C,"CAF",G:G)/COUNTIFS(C:C,"CAF",E:E,1)*100 -> 36.364798
A8: 7 | B8: Uruguay | C8: CONMEBOL | D8: 1147 | E8: =IF(COUNTIF($I$2:$I$33,B8)>0,1,0) -> 1 | F8: =IF(E8=1,"",1/A8) | G8: =IF(E8=1,SUM(F$3:$F7),"") -> 0 | I8: Italy | K8: AFC (Asia) penalty score | L8: =SUMIF(C:C,"AFC",G:G)/COUNTIFS(C:C,"AFC",E:E,1)*100 -> 65.16604
A9: 8 | B9: Colombia | C9: CONMEBOL | D9: 1137 | E9: =IF(COUNTIF($I$2:$I$33,B9)>0,1,0) -> 1 | F9: =IF(E9=1,"",1/A9) | G9: =IF(E9=1,SUM(F$3:$F8),"") -> 0 | I9: Costa Rica
A10: 9 | B10: Italy | C10: UEFA | D10: 1104 | E10: =IF(COUNTIF($I$2:$I$33,B10)>0,1,0) -> 1 | F10: =IF(E10=1,"",1/A10) | G10: =IF(E10=1,SUM(F$3:$F9),"") -> 0 | I10: United States
A11: 10 | B11: England | C11: UEFA | D11: 1090 | E11: =IF(COUNTIF($I$2:$I$33,B11)>0,1,0) -> 1 | F11: =IF(E11=1,"",1/A11) | G11: =IF(E11=1,SUM(F$3:$F10),"") -> 0 | I11: Argentina
A12: 11 | B12: Belgium | C12: UEFA | D12: 1074 | E12: =IF(COUNTIF($I$2:$I$33,B12)>0,1,0) -> 1 | F12: =IF(E12=1,"",1/A12) | G12: =IF(E12=1,SUM(F$3:$F11),"") -> 0 | I12: Belgium
A13: 12 | B13: Greece | C13: UEFA | D13: 1064 | E13: =IF(COUNTIF($I$2:$I$33,B13)>0,1,0) -> 1 | F13: =IF(E13=1,"",1/A13) | G13: =IF(E13=1,SUM(F$3:$F12),"") -> 0 | I13: Switzerland
A14: 13 | B14: United States | C14: CONCACAF | D14: 1035 | E14: =IF(COUNTIF($I$2:$I$33,B14)>0,1,0) -> 1 | F14: =IF(E14=1,"",1/A14) | G14: =IF(E14=1,SUM(F$3:$F13),"") -> 0 | I14: Germany
A15: 14 | B15: Chile | C15: CONMEBOL | D15: 1026 | E15: =IF(COUNTIF($I$2:$I$33,B15)>0,1,0) -> 1 | F15: =IF(E15=1,"",1/A15) | G15: =IF(E15=1,SUM(F$3:$F14),"") -> 0 | I15: Colombia
A16: 15 | B16: Netherlands | C16: UEFA | D16: 981 | E16: =IF(COUNTIF($I$2:$I$33,B16)>0,1,0) -> 1 | F16: =IF(E16=1,"",1/A16) | G16: =IF(E16=1,SUM(F$3:$F15),"") -> 0 | I16: Bosnia and Herzegovina
A17: 16 | B17: Ukraine | C17: UEFA | D17: 915 | E17: =IF(COUNTIF($I$2:$I$33,B17)>0,1,0) -> 0 | F17: =IF(E17=1,"",1/A17) -> 0.0625 | G17: =IF(E17=1,SUM(F$3:$F16),"") | I17: Russia
A18: 17 | B18: France | C18: UEFA | D18: 913 | E18: =IF(COUNTIF($I$2:$I$33,B18)>0,1,0) -> 1 | F18: =IF(E18=1,"",1/A18) | G18: =IF(E18=1,SUM(F$3:$F17),"") -> 0.0625 | I18: England
A19: 18 | B19: Croatia | C19: UEFA | D19: 903 | E19: =IF(COUNTIF($I$2:$I$33,B19)>0,1,0) -> 1 | F19: =IF(E19=1,"",1/A19) | G19: =IF(E19=1,SUM(F$3:$F18),"") -> 0.0625 | I19: Spain
A20: 19 | B20: Russia | C20: UEFA | D20: 893 | E20: =IF(COUNTIF($I$2:$I$33,B20)>0,1,0) -> 1 | F20: =IF(E20=1,"",1/A20) | G20: =IF(E20=1,SUM(F$3:$F19),"") -> 0.0625 | I20: Chile
... A33: 32 | B33: Sweden | C33: UEFA | D33: 741 | E33: =IF(COUNTIF($I$2:$I$33,B33)>0,1,0) -> 0 | F33: =IF(E33=1,"",1/A33) -> 0.03125 | G33: =IF(E33=1,SUM(F$3:$F32),"") | I33: Uruguay
A34: 33 | B34: Honduras | C34: CONCACAF | D34: 731 | E34: =IF(COUNTIF($I$2:$I$33,B34)>0,1,0) -> 1 | F34: =IF(E34=1,"",1/A34) | G34: =IF(E34=1,SUM(F$3:$F33),"") -> 0.31433945
A35: 34 | B35: Czech Republic | C35: UEFA | D35: 724 | E35: =IF(COUNTIF($I$2:$I$33,B35)>0,1,0) -> 0 | F35: =IF(E35=1,"",1/A35) -> 0.029411765 | G35: =IF(E35=1,SUM(F$3:$F34),"")
A36: 35 | B36: Turkey | C36: UEFA | D36: 722 | E36: =IF(COUNTIF($I$2:$I$33,B36)>0,1,0) -> 0 | F36: =IF(E36=1,"",1/A36) -> 0.028571429 | G36: =IF(E36=1,SUM(F$3:$F35),"")
A37: 36 | B37: Egypt | C37: CAF | D37: 715 | E37: =IF(COUNTIF($I$2:$I$33,B37)>0,1,0) -> 0 | F37: =IF(E37=1,"",1/A37) -> 0.027777778 | G37: =IF(E37=1,SUM(F$3:$F36),"")
A38: 37 | B38: Ghana | C38: CAF | D38: 704 | E38: =IF(COUNTIF($I$2:$I$33,B38)>0,1,0) -> 1 | F38: =IF(E38=1,"",1/A38) | G38: =IF(E38=1,SUM(F$3:$F37),"") -> 0.40010043
A39: 38 | B39: Armenia | C39: UEFA | D39: 682 | E39: =IF(COUNTIF($I$2:$I$33,B39)>0,1,0) -> 0 | F39: =IF(E39=1,"",1/A39) -> 0.026315789 | G39: =IF(E39=1,SUM(F$3:$F38),"")
A40: 39 | B40: Cape Verde | C40: CAF | D40: 674 | E40: =IF(COUNTIF($I$2:$I$33,B40)>0,1,0) -> 0 | F40: =IF(E40=1,"",1/A40) -> 0.025641026 | G40: =IF(E40=1,SUM(F$3:$F39),"")
A41: 40 | B41: Venezuela | C41: CONMEBOL | D41: 672 | E41: =IF(COUNTIF($I$2:$I$33,B41)>0,1,0) -> 0 | F41: =IF(E41=1,"",1/A41) -> 0.025 | G41: =IF(E41=1,SUM(F$3:$F40),"")
A42: 41 | B42: Wales | C42: UEFA | D42: 644 | E42: =IF(COUNTIF($I$2:$I$33,B42)>0,1,0) -> 0 | F42: =IF(E42=1,"",1/A42) -> 0.024390244 | G42: =IF(E42=1,SUM(F$3:$F41),"")
A43: 42 | B43: Austria | C43: UEFA | D43: 643 | E43: =IF(COUNTIF($I$2:$I$33,B43)>0,1,0) -> 0 | F43: =IF(E43=1,"",1/A43) -> 0.023809524 | G43: =IF(E43=1,SUM(F$3:$F42),"")
A44: 43 | B44: Iran | C44: AFC | D44: 641 | E44: =IF(COUNTIF($I$2:$I$33,B44)>0,1,0) -> 1 | F44: =IF(E44=1,"",1/A44) | G44: =IF(E44=1,SUM(F$3:$F43),"") -> 0.52525701
A45: 44 | B45: Nigeria | C45: CAF | D45: 640 | E45: =IF(COUNTIF($I$2:$I$33,B45)>0,1,0) -> 1 | F45: =IF(E45=1,"",1/A45) | G45: =IF(E45=1,SUM(F$3:$F44),"") -> 0.52525701
... A76: 75 | B76: Israel | C76: UEFA | D76: 444 | E76: =IF(COUNTIF($I$2:$I$33,B76)>0,1,0) -> 0 | F76: =IF(E76=1,"",1/A76) -> 0.013333333 | G76: =IF(E76=1,SUM(F$3:$F75),"")

Sheet 2018
A1: # | B1: Nation | C1: Confederation | D1: Points | E1: World Cup | F1: Penalty | G1: qualifying penalty | I1: Qualified
A2: 1 | B2: Germany | C2: UEFA | D2: 1558 | E2: =IF(COUNTIF($I$2:$I$33,B2)>0,1,0) -> 1 | F2: =IF(E2=1,"",1/A2) | G2: 0 | I2: Russia
A3: 2 | B3: Brazil | C3: CONMEBOL | D3: 1431 | E3: =IF(COUNTIF($I$2:$I$33,B3)>0,1,0) -> 1 | F3: =IF(E3=1,"",1/A3) | G3: =IF(E3=1,SUM(F2:$F$3),"") -> 0 | I3: Brazil | K3: global penalty score | L3: =SUM(F:F)*(COUNTA(I:I)-1) -> 36.271668
A4: 3 | B4: Belgium | C4: UEFA | D4: 1298 | E4: =IF(COUNTIF($I$2:$I$33,B4)>0,1,0) -> 1 | F4: =IF(E4=1,"",1/A4) | G4: =IF(E4=1,SUM(F3:$F$3),"") -> 0 | I4: Iran | K4: UEFA (Europe) penalty score | L4: =SUMIF(C:C,"UEFA",G:G)/COUNTIFS(C:C,"UEFA",E:E,1)*100 -> 19.904244
A5: 4 | B5: Portugal | C5: UEFA | D5: 1274 | E5: =IF(COUNTIF($I$2:$I$33,B5)>0,1,0) -> 1 | F5: =IF(E5=1,"",1/A5) | G5: =IF(E5=1,SUM(F$3:$F4),"") -> 0 | I5: Japan | K5: CONMEBOL (S. America) penalty score | L5: =SUMIF(C:C,"CONMEBOL",G:G)/COUNTIFS(C:C,"CONMEBOL",E:E,1)*100 -> 6.6666667
A6: 5 | B6: Argentina | C6: CONMEBOL | D6: 1241 | E6: =IF(COUNTIF($I$2:$I$33,B6)>0,1,0) -> 1 | F6: =IF(E6=1,"",1/A6) | G6: =IF(E6=1,SUM(F$3:$F5),"") -> 0 | I6: Mexico | K6: CONCACAF (N. America) penalty score | L6: =SUMIF(C:C,"CONCACAF",G:G)/COUNTIFS(C:C,"CONCACAF",E:E,1)*100 -> 42.604249
A7: 6 | B7: Switzerland | C7: UEFA | D7: 1199 | E7: =IF(COUNTIF($I$2:$I$33,B7)>0,1,0) -> 1 | F7: =IF(E7=1,"",1/A7) | G7: =IF(E7=1,SUM(F$3:$F6),"") -> 0 | I7: Belgium | K7: CAF (Africa) penalty score | L7: =SUMIF(C:C,"CAF",G:G)/COUNTIFS(C:C,"CAF",E:E,1)*100 -> 55.913302
A8: 7 | B8: France | C8: UEFA | D8: 1198 | E8: =IF(COUNTIF($I$2:$I$33,B8)>0,1,0) -> 1 | F8: =IF(E8=1,"",1/A8) | G8: =IF(E8=1,SUM(F$3:$F7),"") -> 0 | I8: South Korea | K8: AFC (Asia) penalty score | L8: =SUMIF(C:C,"AFC",G:G)/COUNTIFS(C:C,"AFC",E:E,1)*100 -> 81.302504
A9: 8 | B9: Poland | C9: UEFA | D9: 1183 | E9: =IF(COUNTIF($I$2:$I$33,B9)>0,1,0) -> 1 | F9: =IF(E9=1,"",1/A9) | G9: =IF(E9=1,SUM(F$3:$F8),"") -> 0 | I9: Saudi Arabia
A10: 9 | B10: Chile | C10: CONMEBOL | D10: 1135 | E10: =IF(COUNTIF($I$2:$I$33,B10)>0,1,0) -> 0 | F10: =IF(E10=1,"",1/A10) -> 0.11111111 | G10: =IF(E10=1,SUM(F$3:$F9),"") | I10: Germany
A11: 10 | B11: Spain | C11: UEFA | D11: 1126 | E11: =IF(COUNTIF($I$2:$I$33,B11)>0,1,0) -> 1 | F11: =IF(E11=1,"",1/A11) | G11: =IF(E11=1,SUM(F$3:$F10),"") -> 0.11111111 | I11: England
A12: 11 | B12: Peru | C12: CONMEBOL | D12: 1125 | E12: =IF(COUNTIF($I$2:$I$33,B12)>0,1,0) -> 1 | F12: =IF(E12=1,"",1/A12) | G12: =IF(E12=1,SUM(F$3:$F11),"") -> 0.11111111 | I12: Spain
A13: 12 | B13: Denmark | C13: UEFA | D13: 1051 | E13: =IF(COUNTIF($I$2:$I$33,B13)>0,1,0) -> 1 | F13: =IF(E13=1,"",1/A13) | G13: =IF(E13=1,SUM(F$3:$F12),"") -> 0.11111111 | I13: Nigeria
A14: 13 | B14: England | C14: UEFA | D14: 1051 | E14: =IF(COUNTIF($I$2:$I$33,B14)>0,1,0) -> 1 | F14: =IF(E14=1,"",1/A14) | G14: =IF(E14=1,SUM(F$3:$F13),"") -> 0.11111111 | I14: Costa Rica
A15: 14 | B15: Uruguay | C15: CONMEBOL | D15: 1018 | E15: =IF(COUNTIF($I$2:$I$33,B15)>0,1,0) -> 1 | F15: =IF(E15=1,"",1/A15) | G15: =IF(E15=1,SUM(F$3:$F14),"") -> 0.11111111 | I15: Poland
A16: 15 | B16: Mexico | C16: CONCACAF | D16: 989 | E16: =IF(COUNTIF($I$2:$I$33,B16)>0,1,0) -> 1 | F16: =IF(E16=1,"",1/A16) | G16: =IF(E16=1,SUM(F$3:$F15),"") -> 0.11111111 | I16: Egypt
A17: 16 | B17: Colombia | C17: CONMEBOL | D17: 986 | E17: =IF(COUNTIF($I$2:$I$33,B17)>0,1,0) -> 1 | F17: =IF(E17=1,"",1/A17) | G17: =IF(E17=1,SUM(F$3:$F16),"") -> 0.11111111 | I17: Iceland
A18: 17 | B18: Netherlands | C18: UEFA | D18: 981 | E18: =IF(COUNTIF($I$2:$I$33,B18)>0,1,0) -> 0 | F18: =IF(E18=1,"",1/A18) -> 0.058823529 | G18: =IF(E18=1,SUM(F$3:$F17),"") | I18: Serbia
A19: 18 | B19: Wales | C19: UEFA | D19: 953 | E19: =IF(COUNTIF($I$2:$I$33,B19)>0,1,0) -> 0 | F19: =IF(E19=1,"",1/A19) -> 0.055555556 | G19: =IF(E19=1,SUM(F$3:$F18),"") | I19: Portugal
A20: 19 | B20: Italy | C20: UEFA | D20: 951 | E20: =IF(COUNTIF($I$2:$I$33,B20)>0,1,0) -> 0 | F20: =IF(E20=1,"",1/A20) -> 0.052631579 | G20: =IF(E20=1,SUM(F$3:$F19),"") | I20: France
... A33: 32 | B33: Paraguay | C33: CONMEBOL | D33: 773 | E33: =IF(COUNTIF($I$2:$I$33,B33)>0,1,0) -> 0 | F33: =IF(E33=1,"",1/A33) -> 0.03125 | G33: =IF(E33=1,SUM(F$3:$F32),"") | I33: Peru
A34: 33 | B34: Venezuela | C34: CONMEBOL | D34: 755 | E34: =IF(COUNTIF($I$2:$I$33,B34)>0,1,0) -> 0 | F34: =IF(E34=1,"",1/A34) -> 0.03030303 | G34: =IF(E34=1,SUM(F$3:$F33),"")
A35: 34 | B35: Serbia | C35: UEFA | D35: 751 | E35: =IF(COUNTIF($I$2:$I$33,B35)>0,1,0) -> 1 | F35: =IF(E35=1,"",1/A35) | G35: =IF(E35=1,SUM(F$3:$F34),"") -> 0.55392479
A36: 35 | B36: Ukraine | C36: UEFA | D36: 733 | E36: =IF(COUNTIF($I$2:$I$33,B36)>0,1,0) -> 0 | F36: =IF(E36=1,"",1/A36) -> 0.028571429 | G36: =IF(E36=1,SUM(F$3:$F35),"")
A37: 36 | B37: Australia | C37: AFC | D37: 718 | E37: =IF(COUNTIF($I$2:$I$33,B37)>0,1,0) -> 1 | F37: =IF(E37=1,"",1/A37) | G37: =IF(E37=1,SUM(F$3:$F36),"") -> 0.58249621
A38: 37 | B38: Iran | C38: AFC | D38: 708 | E38: =IF(COUNTIF($I$2:$I$33,B38)>0,1,0) -> 1 | F38: =IF(E38=1,"",1/A38) | G38: =IF(E38=1,SUM(F$3:$F37),"") -> 0.58249621
A39: 38 | B39: Turkey | C39: UEFA | D39: 706 | E39: =IF(COUNTIF($I$2:$I$33,B39)>0,1,0) -> 0 | F39: =IF(E39=1,"",1/A39) -> 0.026315789 | G39: =IF(E39=1,SUM(F$3:$F38),"")
A40: 39 | B40: Democratic Republic of the Congo | C40: CAF | D40: 706 | E40: =IF(COUNTIF($I$2:$I$33,B40)>0,1,0) -> 0 | F40: =IF(E40=1,"",1/A40) -> 0.025641026 | G40: =IF(E40=1,SUM(F$3:$F39),"")
A41: 40 | B41: Bosnia-Herzegovina | C41: UEFA | D41: 693 | E41: =IF(COUNTIF($I$2:$I$33,B41)>0,1,0) -> 0 | F41: =IF(E41=1,"",1/A41) -> 0.025 | G41: =IF(E41=1,SUM(F$3:$F40),"")
A42: 41 | B42: Morocco | C42: CAF | D42: 686 | E42: =IF(COUNTIF($I$2:$I$33,B42)>0,1,0) -> 1 | F42: =IF(E42=1,"",1/A42) | G42: =IF(E42=1,SUM(F$3:$F41),"") -> 0.65945303
A43: 42 | B43: Scotland | C43: UEFA | D43: 660 | E43: =IF(COUNTIF($I$2:$I$33,B43)>0,1,0) -> 0 | F43: =IF(E43=1,"",1/A43) -> 0.023809524 | G43: =IF(E43=1,SUM(F$3:$F42),"")
A44: 43 | B44: Montenegro | C44: UEFA | D44: 652 | E44: =IF(COUNTIF($I$2:$I$33,B44)>0,1,0) -> 0 | F44: =IF(E44=1,"",1/A44) -> 0.023255814 | G44: =IF(E44=1,SUM(F$3:$F43),"")
A45: 44 | B45: Greece | C45: UEFA | D45: 650 | E45: =IF(COUNTIF($I$2:$I$33,B45)>0,1,0) -> 0 | F45: =IF(E45=1,"",1/A45) -> 0.022727273 | G45: =IF(E45=1,SUM(F$3:$F44),"")
... A76: 75 | B76: China | C76: AFC | D76: 423 | E76: =IF(COUNTIF($I$2:$I$33,B76)>0,1,0) -> 0 | F76: =IF(E76=1,"",1/A76) -> 0.013333333 | G76: =IF(E76=1,SUM(F$3:$F75),"")

Sheet 2022
A1: # | B1: Nation | C1: Confederation | D1: Points | E1: World Cup | F1: Penalty | G1: qualifying penalty | I1: Qualified
A2: 1 | B2: Brazil | C2: CONMEBOL | D2: 1841 | E2: =IF(COUNTIF($I$2:$I$33,B2)>0,1,0) -> 1 | F2: =IF(E2=1,"",1/A2) | G2: 0 | I2: Qatar
A3: 2 | B3: Belgium | C3: UEFA | D3: 1817 | E3: =IF(COUNTIF($I$2:$I$33,B3)>0,1,0) -> 1 | F3: =IF(E3=1,"",1/A3) | G3: =IF(E3=1,SUM(F2:$F$3),"") -> 0 | I3: Germany | K3: global penalty score | L3: =SUM(F:F)*(COUNTA(I:I)-1) -> 35.261065
A4: 3 | B4: Argentina | C4: CONMEBOL | D4: 1774 | E4: =IF(COUNTIF($I$2:$I$33,B4)>0,1,0) -> 1 | F4: =IF(E4=1,"",1/A4) | G4: =IF(E4=1,SUM(F3:$F$3),"") -> 0 | I4: Denmark | K4: UEFA (Europe) penalty score | L4: =SUMIF(C:C,"UEFA",G:G)/COUNTIFS(C:C,"UEFA",E:E,1)*100 -> 14.820119
A5: 4 | B5: France | C5: UEFA | D5: 1760 | E5: =IF(COUNTIF($I$2:$I$33,B5)>0,1,0) -> 1 | F5: =IF(E5=1,"",1/A5) | G5: =IF(E5=1,SUM(F$3:$F4),"") -> 0 | I5: Brazil | K5: CONMEBOL (S. America) penalty score | L5: =SUMIF(C:C,"CONMEBOL",G:G)/COUNTIFS(C:C,"CONMEBOL",E:E,1)*100 -> 19.898662
A6: 5 | B6: England | C6: UEFA | D6: 1728 | E6: =IF(COUNTIF($I$2:$I$33,B6)>0,1,0) -> 1 | F6: =IF(E6=1,"",1/A6) | G6: =IF(E6=1,SUM(F$3:$F5),"") -> 0 | I6: France | K6: CONCACAF (N. America) penalty score | L6: =SUMIF(C:C,"CONCACAF",G:G)/COUNTIFS(C:C,"CONCACAF",E:E,1)*100 -> 32.982297
A7: 6 | B7: Italy | C7: UEFA | D7: 1726 | E7: =IF(COUNTIF($I$2:$I$33,B7)>0,1,0) -> 0 | F7: =IF(E7=1,"",1/A7) -> 0.16666667 | G7: =IF(E7=1,SUM(F$3:$F6),"") | I7: Belgium | K7: CAF (Africa) penalty score | L7: =SUMIF(C:C,"CAF",G:G)/COUNTIFS(C:C,"CAF",E:E,1)*100 -> 47.1513
A8: 7 | B8: Spain | C8: UEFA | D8: 1715 | E8: =IF(COUNTIF($I$2:$I$33,B8)>0,1,0) -> 1 | F8: =IF(E8=1,"",1/A8) | G8: =IF(E8=1,SUM(F$3:$F7),"") -> 0.16666667 | I8: Serbia | K8: AFC (Asia) penalty score | L8: =SUMIF(C:C,"AFC",G:G)/COUNTIFS(C:C,"AFC",E:E,1)*100 -> 47.7802
A9: 8 | B9: Netherlands | C9: UEFA | D9: 1695 | E9: =IF(COUNTIF($I$2:$I$33,B9)>0,1,0) -> 1 | F9: =IF(E9=1,"",1/A9) | G9: =IF(E9=1,SUM(F$3:$F8),"") -> 0.16666667 | I9: Spain
A10: 9 | B10: Portugal | C10: UEFA | D10: 1677 | E10: =IF(COUNTIF($I$2:$I$33,B10)>0,1,0) -> 1 | F10: =IF(E10=1,"",1/A10) | G10: =IF(E10=1,SUM(F$3:$F9),"") -> 0.16666667 | I10: Croatia
A11: 10 | B11: Denmark | C11: UEFA | D11: 1667 | E11: =IF(COUNTIF($I$2:$I$33,B11)>0,1,0) -> 1 | F11: =IF(E11=1,"",1/A11) | G11: =IF(E11=1,SUM(F$3:$F10),"") -> 0.16666667 | I11: Switzerland
A12: 11 | B12: Germany | C12: UEFA | D12: 1650 | E12: =IF(COUNTIF($I$2:$I$33,B12)>0,1,0) -> 1 | F12: =IF(E12=1,"",1/A12) | G12: =IF(E12=1,SUM(F$3:$F11),"") -> 0.16666667 | I12: England
A13: 12 | B13: Croatia | C13: UEFA | D13: 1646 | E13: =IF(COUNTIF($I$2:$I$33,B13)>0,1,0) -> 1 | F13: =IF(E13=1,"",1/A13) | G13: =IF(E13=1,SUM(F$3:$F12),"") -> 0.16666667 | I13: Netherlands
A14: 13 | B14: Mexico | C14: CONCACAF | D14: 1645 | E14: =IF(COUNTIF($I$2:$I$33,B14)>0,1,0) -> 1 | F14: =IF(E14=1,"",1/A14) | G14: =IF(E14=1,SUM(F$3:$F13),"") -> 0.16666667 | I14: Argentina
A15: 14 | B15: Uruguay | C15: CONMEBOL | D15: 1639 | E15: =IF(COUNTIF($I$2:$I$33,B15)>0,1,0) -> 1 | F15: =IF(E15=1,"",1/A15) | G15: =IF(E15=1,SUM(F$3:$F14),"") -> 0.16666667 | I15: Iran
A16: 15 | B16: Switzerland | C16: UEFA | D16: 1636 | E16: =IF(COUNTIF($I$2:$I$33,B16)>0,1,0) -> 1 | F16: =IF(E16=1,"",1/A16) | G16: =IF(E16=1,SUM(F$3:$F15),"") -> 0.16666667 | I16: South Korea
A17: 16 | B17: United States | C17: CONCACAF | D17: 1627 | E17: =IF(COUNTIF($I$2:$I$33,B17)>0,1,0) -> 1 | F17: =IF(E17=1,"",1/A17) | G17: =IF(E17=1,SUM(F$3:$F16),"") -> 0.16666667 | I17: Saudi Arabia
A18: 17 | B18: Colombia | C18: CONMEBOL | D18: 1611 | E18: =IF(COUNTIF($I$2:$I$33,B18)>0,1,0) -> 0 | F18: =IF(E18=1,"",1/A18) -> 0.058823529 | G18: =IF(E18=1,SUM(F$3:$F17),"") | I18: Japan
A19: 18 | B19: Senegal | C19: CAF | D19: 1584 | E19: =IF(COUNTIF($I$2:$I$33,B19)>0,1,0) -> 1 | F19: =IF(E19=1,"",1/A19) | G19: =IF(E19=1,SUM(F$3:$F18),"") -> 0.2254902 | I19: Uruguay
A20: 19 | B20: Wales | C20: UEFA | D20: 1570 | E20: =IF(COUNTIF($I$2:$I$33,B20)>0,1,0) -> 1 | F20: =IF(E20=1,"",1/A20) | G20: =IF(E20=1,SUM(F$3:$F19),"") -> 0.2254902 | I20: Ecuador
... A33: 32 | B33: Nigeria | C33: CAF | D33: 1498 | E33: =IF(COUNTIF($I$2:$I$33,B33)>0,1,0) -> 0 | F33: =IF(E33=1,"",1/A33) -> 0.03125 | G33: =IF(E33=1,SUM(F$3:$F32),"") | I33: Costa Rica
A34: 33 | B34: Russia | C34: UEFA | D34: 1496 | E34: =IF(COUNTIF($I$2:$I$33,B34)>0,1,0) -> 0 | F34: =IF(E34=1,"",1/A34) -> 0.03030303 | G34: =IF(E34=1,SUM(F$3:$F33),"")
A35: 34 | B35: Austria | C35: UEFA | D35: 1493 | E35: =IF(COUNTIF($I$2:$I$33,B35)>0,1,0) -> 0 | F35: =IF(E35=1,"",1/A35) -> 0.029411765 | G35: =IF(E35=1,SUM(F$3:$F34),"")
A36: 35 | B36: Czech Republic | C36: UEFA | D36: 1492 | E36: =IF(COUNTIF($I$2:$I$33,B36)>0,1,0) -> 0 | F36: =IF(E36=1,"",1/A36) -> 0.028571429 | G36: =IF(E36=1,SUM(F$3:$F35),"")
A37: 36 | B37: Hungary | C37: UEFA | D37: 1492 | E37: =IF(COUNTIF($I$2:$I$33,B37)>0,1,0) -> 0 | F37: =IF(E37=1,"",1/A37) -> 0.027777778 | G37: =IF(E37=1,SUM(F$3:$F36),"")
A38: 37 | B38: Algeria | C38: CAF | D38: 1489 | E38: =IF(COUNTIF($I$2:$I$33,B38)>0,1,0) -> 0 | F38: =IF(E38=1,"",1/A38) -> 0.027027027 | G38: =IF(E38=1,SUM(F$3:$F37),"")
A39: 38 | B39: Australia | C39: AFC | D39: 1489 | E39: =IF(COUNTIF($I$2:$I$33,B39)>0,1,0) -> 1 | F39: =IF(E39=1,"",1/A39) | G39: =IF(E39=1,SUM(F$3:$F38),"") -> 0.55482928
A40: 39 | B40: Egypt | C40: CAF | D40: 1486 | E40: =IF(COUNTIF($I$2:$I$33,B40)>0,1,0) -> 0 | F40: =IF(E40=1,"",1/A40) -> 0.025641026 | G40: =IF(E40=1,SUM(F$3:$F39),"")
A41: 40 | B41: Scotland | C41: UEFA | D41: 1480 | E41: =IF(COUNTIF($I$2:$I$33,B41)>0,1,0) -> 0 | F41: =IF(E41=1,"",1/A41) -> 0.025 | G41: =IF(E41=1,SUM(F$3:$F40),"")
A42: 41 | B42: Canada | C42: CONCACAF | D42: 1475 | E42: =IF(COUNTIF($I$2:$I$33,B42)>0,1,0) -> 1 | F42: =IF(E42=1,"",1/A42) | G42: =IF(E42=1,SUM(F$3:$F41),"") -> 0.60547031
A43: 42 | B43: Norway | C43: UEFA | D43: 1473 | E43: =IF(COUNTIF($I$2:$I$33,B43)>0,1,0) -> 0 | F43: =IF(E43=1,"",1/A43) -> 0.023809524 | G43: =IF(E43=1,SUM(F$3:$F42),"")
A44: 43 | B44: Cameroon | C44: CAF | D44: 1471 | E44: =IF(COUNTIF($I$2:$I$33,B44)>0,1,0) -> 1 | F44: =IF(E44=1,"",1/A44) | G44: =IF(E44=1,SUM(F$3:$F43),"") -> 0.62927983
A45: 44 | B45: Ecuador | C45: CONMEBOL | D45: 1464 | E45: =IF(COUNTIF($I$2:$I$33,B45)>0,1,0) -> 1 | F45: =IF(E45=1,"",1/A45) | G45: =IF(E45=1,SUM(F$3:$F44),"") -> 0.62927983
... A76: 75 | B76: Oman | C76: AFC | D76: 1320 | E76: =IF(COUNTIF($I$2:$I$33,B76)>0,1,0) -> 0 | F76: =IF(E76=1,"",1/A76) -> 0.013333333 | G76: =IF(E76=1,SUM(F$3:$F75),"")

Sheet 2026
A1: # | B1: Nation | C1: Confederation | D1: Points | E1: World Cup | F1: Penalty | G1: qualifying penalty | I1: Qualified
A2: 1 | B2: Spain | C2: UEFA | D2: 1877 | E2: =IF(COUNTIF($I$2:$I$49,B2)>0,1,0) -> 1 | F2: =IF(E2=1,"",1/A2) | G2: 0 | I2: Canada
A3: 2 | B3: Argentina | C3: CONMEBOL | D3: 1873 | E3: =IF(COUNTIF($I$2:$I$49,B3)>0,1,0) -> 1 | F3: =IF(E3=1,"",1/A3) | G3: =IF(E3=1,SUM(F2:$F$3),"") -> 0 | I3: Mexico | K3: global penalty score | L3: =SUM(F:F)*(COUNTA(I:I)-1) -> 33.659678
A4: 3 | B4: France | C4: UEFA | D4: 1870 | E4: =IF(COUNTIF($I$2:$I$49,B4)>0,1,0) -> 1 | F4: =IF(E4=1,"",1/A4) | G4: =IF(E4=1,SUM(F3:$F$3),"") -> 0 | I4: United States | K4: UEFA (Europe) penalty score | L4: =SUMIF(C:C,"UEFA",G:G)/COUNTIFS(C:C,"UEFA",E:E,1)*100 -> 13.184387
A5: 4 | B5: England | C5: UEFA | D5: 1834 | E5: =IF(COUNTIF($I$2:$I$49,B5)>0,1,0) -> 1 | F5: =IF(E5=1,"",1/A5) | G5: =IF(E5=1,SUM(F$3:$F4),"") -> 0 | I5: Japan | K5: CONMEBOL (S. America) penalty score | L5: =SUMIF(C:C,"CONMEBOL",G:G)/COUNTIFS(C:C,"CONMEBOL",E:E,1)*100 -> 10.19066
A6: 5 | B6: Brazil | C6: CONMEBOL | D6: 1760 | E6: =IF(COUNTIF($I$2:$I$49,B6)>0,1,0) -> 1 | F6: =IF(E6=1,"",1/A6) | G6: =IF(E6=1,SUM(F$3:$F5),"") -> 0 | I6: New Zealand | K6: CONCACAF (N. America) penalty score | L6: =SUMIF(C:C,"CONCACAF",G:G)/COUNTIFS(C:C,"CONCACAF",E:E,1)*100 -> 11.607143
A7: 6 | B7: Portugal | C7: UEFA | D7: 1760 | E7: =IF(COUNTIF($I$2:$I$49,B7)>0,1,0) -> 1 | F7: =IF(E7=1,"",1/A7) | G7: =IF(E7=1,SUM(F$3:$F6),"") -> 0 | I7: Iran | K7: CAF (Africa) penalty score | L7: =SUMIF(C:C,"CAF",G:G)/COUNTIFS(C:C,"CAF",E:E,1)*100 -> 36.22409
A8: 7 | B8: Netherlands | C8: UEFA | D8: 1756 | E8: =IF(COUNTIF($I$2:$I$49,B8)>0,1,0) -> 1 | F8: =IF(E8=1,"",1/A8) | G8: =IF(E8=1,SUM(F$3:$F7),"") -> 0 | I8: Argentina | K8: AFC (Asia) penalty score | L8: =SUMIF(C:C,"AFC",G:G)/COUNTIFS(C:C,"AFC",E:E,1)*100 -> 33.621793
A9: 8 | B9: Belgium | C9: UEFA | D9: 1731 | E9: =IF(COUNTIF($I$2:$I$49,B9)>0,1,0) -> 1 | F9: =IF(E9=1,"",1/A9) | G9: =IF(E9=1,SUM(F$3:$F8),"") -> 0 | I9: Uzbekistan
A10: 9 | B10: Germany | C10: UEFA | D10: 1724 | E10: =IF(COUNTIF($I$2:$I$49,B10)>0,1,0) -> 1 | F10: =IF(E10=1,"",1/A10) | G10: =IF(E10=1,SUM(F$3:$F9),"") -> 0 | I10: South Korea
A11: 10 | B11: Croatia | C11: UEFA | D11: 1717 | E11: =IF(COUNTIF($I$2:$I$49,B11)>0,1,0) -> 1 | F11: =IF(E11=1,"",1/A11) | G11: =IF(E11=1,SUM(F$3:$F10),"") -> 0 | I11: Jordan
A12: 11 | B12: Morocco | C12: CAF | D12: 1713 | E12: =IF(COUNTIF($I$2:$I$49,B12)>0,1,0) -> 1 | F12: =IF(E12=1,"",1/A12) | G12: =IF(E12=1,SUM(F$3:$F11),"") -> 0 | I12: Australia
A13: 12 | B13: Italy | C13: UEFA | D13: 1702 | E13: =IF(COUNTIF($I$2:$I$49,B13)>0,1,0) -> 0 | F13: =IF(E13=1,"",1/A13) -> 0.083333333 | G13: =IF(E13=1,SUM(F$3:$F12),"") | I13: Brazil
A14: 13 | B14: Colombia | C14: CONMEBOL | D14: 1701 | E14: =IF(COUNTIF($I$2:$I$49,B14)>0,1,0) -> 1 | F14: =IF(E14=1,"",1/A14) | G14: =IF(E14=1,SUM(F$3:$F13),"") -> 0.083333333 | I14: Ecuador
A15: 14 | B15: United States | C15: CONCACAF | D15: 1682 | E15: =IF(COUNTIF($I$2:$I$49,B15)>0,1,0) -> 1 | F15: =IF(E15=1,"",1/A15) | G15: =IF(E15=1,SUM(F$3:$F14),"") -> 0.083333333 | I15: Uruguay
A16: 15 | B16: Mexico | C16: CONCACAF | D16: 1676 | E16: =IF(COUNTIF($I$2:$I$49,B16)>0,1,0) -> 1 | F16: =IF(E16=1,"",1/A16) | G16: =IF(E16=1,SUM(F$3:$F15),"") -> 0.083333333 | I16: Colombia
A17: 16 | B17: Uruguay | C17: CONMEBOL | D17: 1673 | E17: =IF(COUNTIF($I$2:$I$49,B17)>0,1,0) -> 1 | F17: =IF(E17=1,"",1/A17) | G17: =IF(E17=1,SUM(F$3:$F16),"") -> 0.083333333 | I17: Paraguay
A18: 17 | B18: Switzerland | C18: UEFA | D18: 1655 | E18: =IF(COUNTIF($I$2:$I$49,B18)>0,1,0) -> 1 | F18: =IF(E18=1,"",1/A18) | G18: =IF(E18=1,SUM(F$3:$F17),"") -> 0.083333333 | I18: Morocco
A19: 18 | B19: Japan | C19: AFC | D19: 1650 | E19: =IF(COUNTIF($I$2:$I$49,B19)>0,1,0) -> 1 | F19: =IF(E19=1,"",1/A19) | G19: =IF(E19=1,SUM(F$3:$F18),"") -> 0.083333333 | I19: Tunisia
A20: 19 | B20: Senegal | C20: CAF | D20: 1648 | E20: =IF(COUNTIF($I$2:$I$49,B20)>0,1,0) -> 1 | F20: =IF(E20=1,"",1/A20) | G20: =IF(E20=1,SUM(F$3:$F19),"") -> 0.083333333 | I20: Egypt
... A49: 48 | B49: Venezuela | C49: CONMEBOL | D49: 1465 | E49: =IF(COUNTIF($I$2:$I$49,B49)>0,1,0) -> 0 | F49: =IF(E49=1,"",1/A49) -> 0.020833333 | G49: =IF(E49=1,SUM(F$3:$F48),"") | I49: Turkey
A50: 49 | B50: Costa Rica | C50: CONCACAF | D50: 1464 | E50: =IF(COUNTIF($I$2:$I$49,B50)>0,1,0) -> 0 | F50: =IF(E50=1,"",1/A50) -> 0.020408163 | G50: =IF(E50=1,SUM(F$3:$F49),"")
A51: 50 | B51: Uzbekistan | C51: AFC | D51: 1462 | E51: =IF(COUNTIF($I$2:$I$49,B51)>0,1,0) -> 1 | F51: =IF(E51=1,"",1/A51) | G51: =IF(E51=1,SUM(F$3:$F50),"") -> 0.44469027
A52: 51 | B52: Qatar | C52: AFC | D52: 1462 | E52: =IF(COUNTIF($I$2:$I$49,B52)>0,1,0) -> 1 | F52: =IF(E52=1,"",1/A52) | G52: =IF(E52=1,SUM(F$3:$F51),"") -> 0.44469027
A53: 52 | B53: Peru | C53: CONMEBOL | D53: 1460 | E53: =IF(COUNTIF($I$2:$I$49,B53)>0,1,0) -> 0 | F53: =IF(E53=1,"",1/A53) -> 0.019230769 | G53: =IF(E53=1,SUM(F$3:$F52),"")
A54: 53 | B54: Chile | C54: CONMEBOL | D54: 1458 | E54: =IF(COUNTIF($I$2:$I$49,B54)>0,1,0) -> 0 | F54: =IF(E54=1,"",1/A54) -> 0.018867925 | G54: =IF(E54=1,SUM(F$3:$F53),"")
A55: 54 | B55: Mali | C55: CAF | D55: 1455 | E55: =IF(COUNTIF($I$2:$I$49,B55)>0,1,0) -> 0 | F55: =IF(E55=1,"",1/A55) -> 0.018518519 | G55: =IF(E55=1,SUM(F$3:$F54),"")
A56: 55 | B56: Slovenia | C56: UEFA | D56: 1447 | E56: =IF(COUNTIF($I$2:$I$49,B56)>0,1,0) -> 0 | F56: =IF(E56=1,"",1/A56) -> 0.018181818 | G56: =IF(E56=1,SUM(F$3:$F55),"")
A57: 56 | B57: Democratic Republic of the Congo | C57: CAF | D57: 1442 | E57: =IF(COUNTIF($I$2:$I$49,B57)>0,1,0) -> 1 | F57: =IF(E57=1,"",1/A57) | G57: =IF(E57=1,SUM(F$3:$F56),"") -> 0.5194893
A58: 57 | B58: Cameroon | C58: CAF | D58: 1440 | E58: =IF(COUNTIF($I$2:$I$49,B58)>0,1,0) -> 0 | F58: =IF(E58=1,"",1/A58) -> 0.01754386 | G58: =IF(E58=1,SUM(F$3:$F57),"")
